Workbook

Sheet DASHBOARD

Sheet DUES CONTRIBUTIONS

Sheet LEVY CONTRIBUTIONS

Sheet ACCOUNTS

Sheet TREASURER BILL

Sheet TRADING ACCOUNT

Sheet PERSONAL PROFILE

Sheet RECORDS

Sheet YEARLY DUES FEES
B2: YEARLY DUES FEES
B3: NO. | C3: ELDER | D3: TOTAL | E3: 2023 | F3: 2024 | G3: 2025 | H3: 2026 | I3: 2027 | J3: 2028 | K3: 2029 | L3: 2030 | M3: 2031 | N3: 2032
D4: DUES | E4: ¢ | F4: ¢ | G4: ¢ | H4: ¢ | I4: ¢ | J4: ¢ | K4: ¢ | L4: ¢ | M4: ¢
B5: 1 | C5: Alex Ackah | D5: =SUM(E5:N5) -> 3300 | F5: 900 | G5: 1200 | H5: 1200
B6: 2 | C6: Danso Kingsley | D6: =SUM(E6:N6) -> 2400 | G6: 1200 | H6: 1200
B7: 3 | C7: Fanuel Hagan | D7: =SUM(E7:N7) -> 3900 | E7: 600 | F7: 900 | G7: 1200 | H7: 1200
B8: 4 | C8: Frederick Wortey Tawiah | D8: =SUM(E8:N8) -> 3900 | E8: 600 | F8: 900 | G8: 1200 | H8: 1200
B9: 5 | C9: George Yeboah | D9: =SUM(E9:N9) -> 2400 | G9: 1200 | H9: 1200
B10: 6 | C10: Isaac Darko | D10: =SUM(E10:N10) -> 3900 | E10: 600 | F10: 900 | G10: 1200 | H10: 1200
B11: 7 | C11: Isaac Donkor | D11: =SUM(E11:N11) -> 3300 | F11: 900 | G11: 1200 | H11: 1200
B12: 8 | C12: John Aidoo | D12: =SUM(E12:N12) -> 1200 | H12: 1200
B13: 9 | C13: John Darbo | D13: =SUM(E13:N13) -> 2400 | G13: 1200 | H13: 1200
B14: 10 | C14: John Ofosuhene Asare | D14: =SUM(E14:N14) -> 3900 | E14: 600 | F14: 900 | G14: 1200 | H14: 1200
B15: 11 | C15: Johnson Wood | D15: =SUM(E15:N15) -> 3900 | E15: 600 | F15: 900 | G15: 1200 | H15: 1200
B16: 12 | C16: Jonas Wereko | D16: =SUM(E16:N16) -> 3900 | E16: 600 | F16: 900 | G16: 1200 | H16: 1200
B17: 13 | C17: Jonathan Danso Siaw | D17: =SUM(E17:N17) -> 3900 | E17: 600 | F17: 900 | G17: 1200 | H17: 1200
B18: 14 | C18: Joseph Kofi Amanfo | D18: =SUM(E18:N18) -> 3900 | E18: 600 | F18: 900 | G18: 1200 | H18: 1200
B19: 15 | C19: Justice Kojo Acheampong | D19: =SUM(E19:N19) -> 3900 | E19: 600 | F19: 900 | G19: 1200 | H19: 1200
B20: 16 | C20: Just-Mark Kwabena Quansah | D20: =SUM(E20:N20) -> 3900 | E20: 600 | F20: 900 | G20: 1200 | H20: 1200
B21: 17 | C21: Maxwell Ofei Siaw | D21: =SUM(E21:N21) -> 3900 | E21: 600 | F21: 900 | G21: 1200 | H21: 1200
B22: 18 | C22: Moses Oduro | D22: =SUM(E22:N22) -> 3900 | E22: 600 | F22: 900 | G22: 1200 | H22: 1200
B23: 19 | C23: Osei Kwame | D23: =SUM(E23:N23) -> 3900 | E23: 600 | F23: 900 | G23: 1200 | H23: 1200
B24: 20 | C24: Peter Kingsford Nkrumah | D24: =SUM(E24:N24) -> 3900 | E24: 600 | F24: 900 | G24: 1200 | H24: 1200
B25: 21 | C25: Prince Asante Ahwireng | D25: =SUM(E25:N25) -> 3900 | E25: 600 | F25: 900 | G25: 1200 | H25: 1200
... B28: 24 | C28: William Kojo Anane | D28: =SUM(E28:N28) -> 3900 | E28: 600 | F28: 900 | G28: 1200 | H28: 1200
B30: TOTAL | D30: =SUBTOTAL(9,D5:D28) -> 85200 | E30: =SUBTOTAL(9,E5:E28) -> 10800 | F30: =SUBTOTAL(9,F5:F28) -> 18000 | G30: =SUBTOTAL(9,G5:G28) -> 27600 | H30: =SUBTOTAL(9,H5:H28) -> 28800 | I30: =SUBTOTAL(9,I5:I28) -> 0 | J30: =SUBTOTAL(9,J5:J28) -> 0 | K30: =SUBTOTAL(9,K5:K28) -> 0 | ... N30: =SUBTOTAL(9,N5:N28) -> 0
B31: COUNT | D31: =COUNTIF(D5:D29,">0") -> 24 | E31: =COUNTIF(E5:E29,">0") -> 18 | F31: =COUNTIF(F5:F29,">0") -> 20 | G31: =COUNTIF(G5:G29,">0") -> 23 | H31: =COUNTIF(H5:H29,">0") -> 24 | I31: =COUNTIF(I5:I29,">0") -> 0 | J31: =COUNTIF(J5:J29,">0") -> 0 | K31: =COUNTIF(K5:K29,">0") -> 0 | ... N31: =COUNTIF(N5:N29,">0") -> 0

Sheet YEARLY DUES
B2: YEARLY DUES
B3: NO. | C3: ELDER | D3: TOTAL | E3: 2023 | F3: 2024 | G3: 2025 | H3: 2026 | I3: 2027 | J3: 2028 | K3: 2029 | L3: 2030 | M3: 2031 | N3: 2032
D4: DUES | E4: ¢ | F4: ¢ | G4: ¢ | H4: ¢ | I4: ¢ | J4: ¢ | K4: ¢ | L4: ¢ | M4: ¢
B5: 1 | C5: Alex Ackah | D5: =SUM(E5:N5) -> 3000 | E5: =IFERROR(VLOOKUP($C5,'MONTHLY DUES 2023'!$C$5:$D$25,2,0),0) -> 0 | F5: =IFERROR(VLOOKUP($C5,'MONTHLY DUES 2024'!$C$5:$D$25,2,0),0) -> 900 | G5: =IFERROR(VLOOKUP($C5,'MONTHLY DUES 2025'!$C$5:$D$25,2,0),0) -> 1200 | H5: =IFERROR(VLOOKUP($C5,'MONTHLY DUES 2026'!$C$5:$D$26,2,0),0) -> 900 | I5: =IFERROR(VLOOKUP($C5,'MONTHLY DUES 2027'!$C$5:$D$27,2,0),0) -> 0 | J5: =IFERROR(VLOOKUP($C5,'MONTHLY DUES 2028'!$C$5:$D$27,2,0),0) -> 0 | K5: =IFERROR(VLOOKUP($C5,'MONTHLY DUES 2029'!$C$5:$D$27,2,0),0) -> 0 | L5: =IFERROR(VLOOKUP($C5,'MONTHLY DUES 2030'!$C$5:$D$27,2,0),0) -> 0 | M5: =IFERROR(VLOOKUP($C5,'MONTHLY DUES 2031'!$C$5:$D$27,2,0),0) -> 0 | N5: =IFERROR(VLOOKUP($C5,'MONTHLY DUES 2032'!$C$5:$D$27,2,0),0) -> 0
B6: 2 | C6: Danso Kingsley | D6: =SUM(E6:N6) -> 1500 | E6: =IFERROR(VLOOKUP($C6,'MONTHLY DUES 2023'!$C$5:$D$25,2,0),0) -> 0 | F6: =IFERROR(VLOOKUP($C6,'MONTHLY DUES 2024'!$C$5:$D$25,2,0),0) -> 0 | G6: =IFERROR(VLOOKUP($C6,'MONTHLY DUES 2025'!$C$5:$D$25,2,0),0) -> 1200 | H6: =IFERROR(VLOOKUP($C6,'MONTHLY DUES 2026'!$C$5:$D$26,2,0),0) -> 300 | I6: =IFERROR(VLOOKUP($C6,'MONTHLY DUES 2027'!$C$5:$D$27,2,0),0) -> 0 | J6: =IFERROR(VLOOKUP($C6,'MONTHLY DUES 2028'!$C$5:$D$27,2,0),0) -> 0 | K6: =IFERROR(VLOOKUP($C6,'MONTHLY DUES 2029'!$C$5:$D$27,2,0),0) -> 0 | L6: =IFERROR(VLOOKUP($C6,'MONTHLY DUES 2030'!$C$5:$D$27,2,0),0) -> 0 | M6: =IFERROR(VLOOKUP($C6,'MONTHLY DUES 2031'!$C$5:$D$27,2,0),0) -> 0 | N6: =IFERROR(VLOOKUP($C6,'MONTHLY DUES 2032'!$C$5:$D$27,2,0),0) -> 0
B7: 3 | C7: Fanuel Hagan | D7: =SUM(E7:N7) -> 3400 | E7: =IFERROR(VLOOKUP($C7,'MONTHLY DUES 2023'!$C$5:$D$25,2,0),0) -> 600 | F7: =IFERROR(VLOOKUP($C7,'MONTHLY DUES 2024'!$C$5:$D$25,2,0),0) -> 900 | G7: =IFERROR(VLOOKUP($C7,'MONTHLY DUES 2025'!$C$5:$D$25,2,0),0) -> 1200 | H7: =IFERROR(VLOOKUP($C7,'MONTHLY DUES 2026'!$C$5:$D$26,2,0),0) -> 700 | I7: =IFERROR(VLOOKUP($C7,'MONTHLY DUES 2027'!$C$5:$D$27,2,0),0) -> 0 | J7: =IFERROR(VLOOKUP($C7,'MONTHLY DUES 2028'!$C$5:$D$27,2,0),0) -> 0 | K7: =IFERROR(VLOOKUP($C7,'MONTHLY DUES 2029'!$C$5:$D$27,2,0),0) -> 0 | L7: =IFERROR(VLOOKUP($C7,'MONTHLY DUES 2030'!$C$5:$D$27,2,0),0) -> 0 | M7: =IFERROR(VLOOKUP($C7,'MONTHLY DUES 2031'!$C$5:$D$27,2,0),0) -> 0 | N7: =IFERROR(VLOOKUP($C7,'MONTHLY DUES 2032'!$C$5:$D$27,2,0),0) -> 0
B8: 4 | C8: Frederick Wortey Tawiah | D8: =SUM(E8:N8) -> 3400 | E8: =IFERROR(VLOOKUP($C8,'MONTHLY DUES 2023'!$C$5:$D$25,2,0),0) -> 600 | F8: =IFERROR(VLOOKUP($C8,'MONTHLY DUES 2024'!$C$5:$D$25,2,0),0) -> 900 | G8: =IFERROR(VLOOKUP($C8,'MONTHLY DUES 2025'!$C$5:$D$25,2,0),0) -> 1200 | H8: =IFERROR(VLOOKUP($C8,'MONTHLY DUES 2026'!$C$5:$D$26,2,0),0) -> 700 | I8: =IFERROR(VLOOKUP($C8,'MONTHLY DUES 2027'!$C$5:$D$27,2,0),0) -> 0 | J8: =IFERROR(VLOOKUP($C8,'MONTHLY DUES 2028'!$C$5:$D$27,2,0),0) -> 0 | K8: =IFERROR(VLOOKUP($C8,'MONTHLY DUES 2029'!$C$5:$D$27,2,0),0) -> 0 | L8: =IFERROR(VLOOKUP($C8,'MONTHLY DUES 2030'!$C$5:$D$27,2,0),0) -> 0 | M8: =IFERROR(VLOOKUP($C8,'MONTHLY DUES 2031'!$C$5:$D$27,2,0),0) -> 0 | N8: =IFERROR(VLOOKUP($C8,'MONTHLY DUES 2032'!$C$5:$D$27,2,0),0) -> 0
B9: 5 | C9: George Yeboah | D9: =SUM(E9:N9) -> 200 | E9: =IFERROR(VLOOKUP($C9,'MONTHLY DUES 2023'!$C$5:$D$25,2,0),0) -> 0 | F9: =IFERROR(VLOOKUP($C9,'MONTHLY DUES 2024'!$C$5:$D$25,2,0),0) -> 0 | G9: =IFERROR(VLOOKUP($C9,'MONTHLY DUES 2025'!$C$5:$D$25,2,0),0) -> 200 | H9: =IFERROR(VLOOKUP($C9,'MONTHLY DUES 2026'!$C$5:$D$26,2,0),0) -> 0 | I9: =IFERROR(VLOOKUP($C9,'MONTHLY DUES 2027'!$C$5:$D$27,2,0),0) -> 0 | J9: =IFERROR(VLOOKUP($C9,'MONTHLY DUES 2028'!$C$5:$D$27,2,0),0) -> 0 | K9: =IFERROR(VLOOKUP($C9,'MONTHLY DUES 2029'!$C$5:$D$27,2,0),0) -> 0 | L9: =IFERROR(VLOOKUP($C9,'MONTHLY DUES 2030'!$C$5:$D$27,2,0),0) -> 0 | M9: =IFERROR(VLOOKUP($C9,'MONTHLY DUES 2031'!$C$5:$D$27,2,0),0) -> 0 | N9: =IFERROR(VLOOKUP($C9,'MONTHLY DUES 2032'!$C$5:$D$27,2,0),0) -> 0
B10: 6 | C10: Isaac Darko | D10: =SUM(E10:N10) -> 3900 | E10: =IFERROR(VLOOKUP($C10,'MONTHLY DUES 2023'!$C$5:$D$25,2,0),0) -> 600 | F10: =IFERROR(VLOOKUP($C10,'MONTHLY DUES 2024'!$C$5:$D$25,2,0),0) -> 900 | G10: =IFERROR(VLOOKUP($C10,'MONTHLY DUES 2025'!$C$5:$D$25,2,0),0) -> 1200 | H10: =IFERROR(VLOOKUP($C10,'MONTHLY DUES 2026'!$C$5:$D$26,2,0),0) -> 1200 | I10: =IFERROR(VLOOKUP($C10,'MONTHLY DUES 2027'!$C$5:$D$27,2,0),0) -> 0 | J10: =IFERROR(VLOOKUP($C10,'MONTHLY DUES 2028'!$C$5:$D$27,2,0),0) -> 0 | K10: =IFERROR(VLOOKUP($C10,'MONTHLY DUES 2029'!$C$5:$D$27,2,0),0) -> 0 | L10: =IFERROR(VLOOKUP($C10,'MONTHLY DUES 2030'!$C$5:$D$27,2,0),0) -> 0 | M10: =IFERROR(VLOOKUP($C10,'MONTHLY DUES 2031'!$C$5:$D$27,2,0),0) -> 0 | N10: =IFERROR(VLOOKUP($C10,'MONTHLY DUES 2032'!$C$5:$D$27,2,0),0) -> 0
B11: 7 | C11: Isaac Donkor | D11: =SUM(E11:N11) -> 3300 | E11: =IFERROR(VLOOKUP($C11,'MONTHLY DUES 2023'!$C$5:$D$25,2,0),0) -> 0 | F11: =IFERROR(VLOOKUP($C11,'MONTHLY DUES 2024'!$C$5:$D$25,2,0),0) -> 900 | G11: =IFERROR(VLOOKUP($C11,'MONTHLY DUES 2025'!$C$5:$D$25,2,0),0) -> 1200 | H11: =IFERROR(VLOOKUP($C11,'MONTHLY DUES 2026'!$C$5:$D$26,2,0),0) -> 1200
B12: 55 | C12: John Aidoo | D12: =SUM(E12:N12) -> 900 | E12: =IFERROR(VLOOKUP($C12,'MONTHLY DUES 2023'!$C$5:$D$25,2,0),0) -> 0 | F12: =IFERROR(VLOOKUP($C12,'MONTHLY DUES 2024'!$C$5:$D$25,2,0),0) -> 0 | G12: =IFERROR(VLOOKUP($C12,'MONTHLY DUES 2025'!$C$5:$D$25,2,0),0) -> 0 | H12: =IFERROR(VLOOKUP($C12,'MONTHLY DUES 2026'!$C$5:$D$26,2,0),0) -> 900
B13: 8 | C13: John Darbo | D13: =SUM(E13:N13) -> 350 | E13: =IFERROR(VLOOKUP($C13,'MONTHLY DUES 2023'!$C$5:$D$25,2,0),0) -> 0 | F13: =IFERROR(VLOOKUP($C13,'MONTHLY DUES 2024'!$C$5:$D$25,2,0),0) -> 0 | G13: =IFERROR(VLOOKUP($C13,'MONTHLY DUES 2025'!$C$5:$D$25,2,0),0) -> 350 | H13: =IFERROR(VLOOKUP($C13,'MONTHLY DUES 2026'!$C$5:$D$26,2,0),0) -> 0 | I13: =IFERROR(VLOOKUP($C13,'MONTHLY DUES 2027'!$C$5:$D$27,2,0),0) -> 0 | J13: =IFERROR(VLOOKUP($C13,'MONTHLY DUES 2028'!$C$5:$D$27,2,0),0) -> 0 | K13: =IFERROR(VLOOKUP($C13,'MONTHLY DUES 2029'!$C$5:$D$27,2,0),0) -> 0 | L13: =IFERROR(VLOOKUP($C13,'MONTHLY DUES 2030'!$C$5:$D$27,2,0),0) -> 0 | M13: =IFERROR(VLOOKUP($C13,'MONTHLY DUES 2031'!$C$5:$D$27,2,0),0) -> 0 | N13: =IFERROR(VLOOKUP($C13,'MONTHLY DUES 2032'!$C$5:$D$27,2,0),0) -> 0
B14: 9 | C14: John Ofosuhene Asare | D14: =SUM(E14:N14) -> 3400 | E14: =IFERROR(VLOOKUP($C14,'MONTHLY DUES 2023'!$C$5:$D$25,2,0),0) -> 600 | F14: =IFERROR(VLOOKUP($C14,'MONTHLY DUES 2024'!$C$5:$D$25,2,0),0) -> 900 | G14: =IFERROR(VLOOKUP($C14,'MONTHLY DUES 2025'!$C$5:$D$25,2,0),0) -> 1200 | H14: =IFERROR(VLOOKUP($C14,'MONTHLY DUES 2026'!$C$5:$D$26,2,0),0) -> 700 | I14: =IFERROR(VLOOKUP($C14,'MONTHLY DUES 2027'!$C$5:$D$27,2,0),0) -> 0 | J14: =IFERROR(VLOOKUP($C14,'MONTHLY DUES 2028'!$C$5:$D$27,2,0),0) -> 0 | K14: =IFERROR(VLOOKUP($C14,'MONTHLY DUES 2029'!$C$5:$D$27,2,0),0) -> 0 | L14: =IFERROR(VLOOKUP($C14,'MONTHLY DUES 2030'!$C$5:$D$27,2,0),0) -> 0 | M14: =IFERROR(VLOOKUP($C14,'MONTHLY DUES 2031'!$C$5:$D$27,2,0),0) -> 0 | N14: =IFERROR(VLOOKUP($C14,'MONTHLY DUES 2032'!$C$5:$D$27,2,0),0) -> 0
B15: 10 | C15: Johnson Wood | D15: =SUM(E15:N15) -> 3500 | E15: =IFERROR(VLOOKUP($C15,'MONTHLY DUES 2023'!$C$5:$D$25,2,0),0) -> 600 | F15: =IFERROR(VLOOKUP($C15,'MONTHLY DUES 2024'!$C$5:$D$25,2,0),0) -> 900 | G15: =IFERROR(VLOOKUP($C15,'MONTHLY DUES 2025'!$C$5:$D$25,2,0),0) -> 1200 | H15: =IFERROR(VLOOKUP($C15,'MONTHLY DUES 2026'!$C$5:$D$26,2,0),0) -> 800 | I15: =IFERROR(VLOOKUP($C15,'MONTHLY DUES 2027'!$C$5:$D$27,2,0),0) -> 0 | J15: =IFERROR(VLOOKUP($C15,'MONTHLY DUES 2028'!$C$5:$D$27,2,0),0) -> 0 | K15: =IFERROR(VLOOKUP($C15,'MONTHLY DUES 2029'!$C$5:$D$27,2,0),0) -> 0 | L15: =IFERROR(VLOOKUP($C15,'MONTHLY DUES 2030'!$C$5:$D$27,2,0),0) -> 0 | M15: =IFERROR(VLOOKUP($C15,'MONTHLY DUES 2031'!$C$5:$D$27,2,0),0) -> 0 | N15: =IFERROR(VLOOKUP($C15,'MONTHLY DUES 2032'!$C$5:$D$27,2,0),0) -> 0
B16: 11 | C16: Jonas Wereko | D16: =SUM(E16:N16) -> 3600 | E16: =IFERROR(VLOOKUP($C16,'MONTHLY DUES 2023'!$C$5:$D$25,2,0),0) -> 600 | F16: =IFERROR(VLOOKUP($C16,'MONTHLY DUES 2024'!$C$5:$D$25,2,0),0) -> 900 | G16: =IFERROR(VLOOKUP($C16,'MONTHLY DUES 2025'!$C$5:$D$25,2,0),0) -> 1200 | H16: =IFERROR(VLOOKUP($C16,'MONTHLY DUES 2026'!$C$5:$D$26,2,0),0) -> 900 | I16: =IFERROR(VLOOKUP($C16,'MONTHLY DUES 2027'!$C$5:$D$27,2,0),0) -> 0 | J16: =IFERROR(VLOOKUP($C16,'MONTHLY DUES 2028'!$C$5:$D$27,2,0),0) -> 0 | K16: =IFERROR(VLOOKUP($C16,'MONTHLY DUES 2029'!$C$5:$D$27,2,0),0) -> 0 | L16: =IFERROR(VLOOKUP($C16,'MONTHLY DUES 2030'!$C$5:$D$27,2,0),0) -> 0 | M16: =IFERROR(VLOOKUP($C16,'MONTHLY DUES 2031'!$C$5:$D$27,2,0),0) -> 0 | N16: =IFERROR(VLOOKUP($C16,'MONTHLY DUES 2032'!$C$5:$D$27,2,0),0) -> 0
B17: 12 | C17: Jonathan Danso Siaw | D17: =SUM(E17:N17) -> 3900 | E17: =IFERROR(VLOOKUP($C17,'MONTHLY DUES 2023'!$C$5:$D$25,2,0),0) -> 600 | F17: =IFERROR(VLOOKUP($C17,'MONTHLY DUES 2024'!$C$5:$D$25,2,0),0) -> 900 | G17: =IFERROR(VLOOKUP($C17,'MONTHLY DUES 2025'!$C$5:$D$25,2,0),0) -> 1200 | H17: =IFERROR(VLOOKUP($C17,'MONTHLY DUES 2026'!$C$5:$D$26,2,0),0) -> 1200 | I17: =IFERROR(VLOOKUP($C17,'MONTHLY DUES 2027'!$C$5:$D$27,2,0),0) -> 0 | J17: =IFERROR(VLOOKUP($C17,'MONTHLY DUES 2028'!$C$5:$D$27,2,0),0) -> 0 | K17: =IFERROR(VLOOKUP($C17,'MONTHLY DUES 2029'!$C$5:$D$27,2,0),0) -> 0 | L17: =IFERROR(VLOOKUP($C17,'MONTHLY DUES 2030'!$C$5:$D$27,2,0),0) -> 0 | M17: =IFERROR(VLOOKUP($C17,'MONTHLY DUES 2031'!$C$5:$D$27,2,0),0) -> 0 | N17: =IFERROR(VLOOKUP($C17,'MONTHLY DUES 2032'!$C$5:$D$27,2,0),0) -> 0
B18: 13 | C18: Joseph Kofi Amanfo | D18: =SUM(E18:N18) -> 1000 | E18: =IFERROR(VLOOKUP($C18,'MONTHLY DUES 2023'!$C$5:$D$25,2,0),0) -> 600 | F18: =IFERROR(VLOOKUP($C18,'MONTHLY DUES 2024'!$C$5:$D$25,2,0),0) -> 400 | G18: =IFERROR(VLOOKUP($C18,'MONTHLY DUES 2025'!$C$5:$D$25,2,0),0) -> 0 | H18: =IFERROR(VLOOKUP($C18,'MONTHLY DUES 2026'!$C$5:$D$26,2,0),0) -> 0 | I18: =IFERROR(VLOOKUP($C18,'MONTHLY DUES 2027'!$C$5:$D$27,2,0),0) -> 0 | J18: =IFERROR(VLOOKUP($C18,'MONTHLY DUES 2028'!$C$5:$D$27,2,0),0) -> 0 | K18: =IFERROR(VLOOKUP($C18,'MONTHLY DUES 2029'!$C$5:$D$27,2,0),0) -> 0 | L18: =IFERROR(VLOOKUP($C18,'MONTHLY DUES 2030'!$C$5:$D$27,2,0),0) -> 0 | M18: =IFERROR(VLOOKUP($C18,'MONTHLY DUES 2031'!$C$5:$D$27,2,0),0) -> 0 | N18: =IFERROR(VLOOKUP($C18,'MONTHLY DUES 2032'!$C$5:$D$27,2,0),0) -> 0
B19: 14 | C19: Justice Kojo Acheampong | D19: =SUM(E19:N19) -> 3000 | E19: =IFERROR(VLOOKUP($C19,'MONTHLY DUES 2023'!$C$5:$D$25,2,0),0) -> 600 | F19: =IFERROR(VLOOKUP($C19,'MONTHLY DUES 2024'!$C$5:$D$25,2,0),0) -> 900 | G19: =IFERROR(VLOOKUP($C19,'MONTHLY DUES 2025'!$C$5:$D$25,2,0),0) -> 1200 | H19: =IFERROR(VLOOKUP($C19,'MONTHLY DUES 2026'!$C$5:$D$26,2,0),0) -> 300 | I19: =IFERROR(VLOOKUP($C19,'MONTHLY DUES 2027'!$C$5:$D$27,2,0),0) -> 0 | J19: =IFERROR(VLOOKUP($C19,'MONTHLY DUES 2028'!$C$5:$D$27,2,0),0) -> 0 | K19: =IFERROR(VLOOKUP($C19,'MONTHLY DUES 2029'!$C$5:$D$27,2,0),0) -> 0 | L19: =IFERROR(VLOOKUP($C19,'MONTHLY DUES 2030'!$C$5:$D$27,2,0),0) -> 0 | M19: =IFERROR(VLOOKUP($C19,'MONTHLY DUES 2031'!$C$5:$D$27,2,0),0) -> 0 | N19: =IFERROR(VLOOKUP($C19,'MONTHLY DUES 2032'!$C$5:$D$27,2,0),0) -> 0
B20: 15 | C20: Just-Mark Kwabena Quansah | D20: =SUM(E20:N20) -> 3000 | E20: =IFERROR(VLOOKUP($C20,'MONTHLY DUES 2023'!$C$5:$D$25,2,0),0) -> 600 | F20: =IFERROR(VLOOKUP($C20,'MONTHLY DUES 2024'!$C$5:$D$25,2,0),0) -> 900 | G20: =IFERROR(VLOOKUP($C20,'MONTHLY DUES 2025'!$C$5:$D$25,2,0),0) -> 1200 | H20: =IFERROR(VLOOKUP($C20,'MONTHLY DUES 2026'!$C$5:$D$26,2,0),0) -> 300 | I20: =IFERROR(VLOOKUP($C20,'MONTHLY DUES 2027'!$C$5:$D$27,2,0),0) -> 0 | J20: =IFERROR(VLOOKUP($C20,'MONTHLY DUES 2028'!$C$5:$D$27,2,0),0) -> 0 | K20: =IFERROR(VLOOKUP($C20,'MONTHLY DUES 2029'!$C$5:$D$27,2,0),0) -> 0 | L20: =IFERROR(VLOOKUP($C20,'MONTHLY DUES 2030'!$C$5:$D$27,2,0),0) -> 0 | M20: =IFERROR(VLOOKUP($C20,'MONTHLY DUES 2031'!$C$5:$D$27,2,0),0) -> 0 | N20: =IFERROR(VLOOKUP($C20,'MONTHLY DUES 2032'!$C$5:$D$27,2,0),0) -> 0
B21: 16 | C21: Maxwell Ofei Siaw | D21: =SUM(E21:N21) -> 3700 | E21: =IFERROR(VLOOKUP($C21,'MONTHLY DUES 2023'!$C$5:$D$25,2,0),0) -> 600 | F21: =IFERROR(VLOOKUP($C21,'MONTHLY DUES 2024'!$C$5:$D$25,2,0),0) -> 900 | G21: =IFERROR(VLOOKUP($C21,'MONTHLY DUES 2025'!$C$5:$D$25,2,0),0) -> 1200 | H21: =IFERROR(VLOOKUP($C21,'MONTHLY DUES 2026'!$C$5:$D$26,2,0),0) -> 1000 | I21: =IFERROR(VLOOKUP($C21,'MONTHLY DUES 2027'!$C$5:$D$27,2,0),0) -> 0 | J21: =IFERROR(VLOOKUP($C21,'MONTHLY DUES 2028'!$C$5:$D$27,2,0),0) -> 0 | K21: =IFERROR(VLOOKUP($C21,'MONTHLY DUES 2029'!$C$5:$D$27,2,0),0) -> 0 | L21: =IFERROR(VLOOKUP($C21,'MONTHLY DUES 2030'!$C$5:$D$27,2,0),0) -> 0 | M21: =IFERROR(VLOOKUP($C21,'MONTHLY DUES 2031'!$C$5:$D$27,2,0),0) -> 0 | N21: =IFERROR(VLOOKUP($C21,'MONTHLY DUES 2032'!$C$5:$D$27,2,0),0) -> 0
B22: 17 | C22: Moses Oduro | D22: =SUM(E22:N22) -> 3900 | E22: =IFERROR(VLOOKUP($C22,'MONTHLY DUES 2023'!$C$5:$D$25,2,0),0) -> 600 | F22: =IFERROR(VLOOKUP($C22,'MONTHLY DUES 2024'!$C$5:$D$25,2,0),0) -> 900 | G22: =IFERROR(VLOOKUP($C22,'MONTHLY DUES 2025'!$C$5:$D$25,2,0),0) -> 1200 | H22: =IFERROR(VLOOKUP($C22,'MONTHLY DUES 2026'!$C$5:$D$26,2,0),0) -> 1200 | I22: =IFERROR(VLOOKUP($C22,'MONTHLY DUES 2027'!$C$5:$D$27,2,0),0) -> 0 | J22: =IFERROR(VLOOKUP($C22,'MONTHLY DUES 2028'!$C$5:$D$27,2,0),0) -> 0 | K22: =IFERROR(VLOOKUP($C22,'MONTHLY DUES 2029'!$C$5:$D$27,2,0),0) -> 0 | L22: =IFERROR(VLOOKUP($C22,'MONTHLY DUES 2030'!$C$5:$D$27,2,0),0) -> 0 | M22: =IFERROR(VLOOKUP($C22,'MONTHLY DUES 2031'!$C$5:$D$27,2,0),0) -> 0 | N22: =IFERROR(VLOOKUP($C22,'MONTHLY DUES 2032'!$C$5:$D$27,2,0),0) -> 0
B23: 18 | C23: Osei Kwame | D23: =SUM(E23:N23) -> 3500 | E23: =IFERROR(VLOOKUP($C23,'MONTHLY DUES 2023'!$C$5:$D$25,2,0),0) -> 600 | F23: =IFERROR(VLOOKUP($C23,'MONTHLY DUES 2024'!$C$5:$D$25,2,0),0) -> 900 | G23: =IFERROR(VLOOKUP($C23,'MONTHLY DUES 2025'!$C$5:$D$25,2,0),0) -> 1200 | H23: =IFERROR(VLOOKUP($C23,'MONTHLY DUES 2026'!$C$5:$D$26,2,0),0) -> 800 | I23: =IFERROR(VLOOKUP($C23,'MONTHLY DUES 2027'!$C$5:$D$27,2,0),0) -> 0 | J23: =IFERROR(VLOOKUP($C23,'MONTHLY DUES 2028'!$C$5:$D$27,2,0),0) -> 0 | K23: =IFERROR(VLOOKUP($C23,'MONTHLY DUES 2029'!$C$5:$D$27,2,0),0) -> 0 | L23: =IFERROR(VLOOKUP($C23,'MONTHLY DUES 2030'!$C$5:$D$27,2,0),0) -> 0 | M23: =IFERROR(VLOOKUP($C23,'MONTHLY DUES 2031'!$C$5:$D$27,2,0),0) -> 0 | N23: =IFERROR(VLOOKUP($C23,'MONTHLY DUES 2032'!$C$5:$D$27,2,0),0) -> 0
B24: 19 | C24: Peter Kingsford Nkrumah | D24: =SUM(E24:N24) -> 900 | E24: =IFERROR(VLOOKUP($C24,'MONTHLY DUES 2023'!$C$5:$D$25,2,0),0) -> 600 | F24: =IFERROR(VLOOKUP($C24,'MONTHLY DUES 2024'!$C$5:$D$25,2,0),0) -> 300 | G24: =IFERROR(VLOOKUP($C24,'MONTHLY DUES 2025'!$C$5:$D$25,2,0),0) -> 0 | H24: =IFERROR(VLOOKUP($C24,'MONTHLY DUES 2026'!$C$5:$D$26,2,0),0) -> 0 | I24: =IFERROR(VLOOKUP($C24,'MONTHLY DUES 2027'!$C$5:$D$27,2,0),0) -> 0 | J24: =IFERROR(VLOOKUP($C24,'MONTHLY DUES 2028'!$C$5:$D$27,2,0),0) -> 0 | K24: =IFERROR(VLOOKUP($C24,'MONTHLY DUES 2029'!$C$5:$D$27,2,0),0) -> 0 | L24: =IFERROR(VLOOKUP($C24,'MONTHLY DUES 2030'!$C$5:$D$27,2,0),0) -> 0 | M24: =IFERROR(VLOOKUP($C24,'MONTHLY DUES 2031'!$C$5:$D$27,2,0),0) -> 0 | N24: =IFERROR(VLOOKUP($C24,'MONTHLY DUES 2032'!$C$5:$D$27,2,0),0) -> 0
... B28: 23 | C28: William Kojo Anane | D28: =SUM(E28:N28) -> 3900 | E28: =IFERROR(VLOOKUP($C28,'MONTHLY DUES 2023'!$C$5:$D$25,2,0),0) -> 600 | F28: =IFERROR(VLOOKUP($C28,'MONTHLY DUES 2024'!$C$5:$D$25,2,0),0) -> 900 | G28: =IFERROR(VLOOKUP($C28,'MONTHLY DUES 2025'!$C$5:$D$25,2,0),0) -> 1200 | H28: =IFERROR(VLOOKUP($C28,'MONTHLY DUES 2026'!$C$5:$D$26,2,0),0) -> 1200 | I28: =IFERROR(VLOOKUP($C28,'MONTHLY DUES 2027'!$C$5:$D$27,2,0),0) -> 0 | J28: =IFERROR(VLOOKUP($C28,'MONTHLY DUES 2028'!$C$5:$D$27,2,0),0) -> 0 | K28: =IFERROR(VLOOKUP($C28,'MONTHLY DUES 2029'!$C$5:$D$27,2,0),0) -> 0 | L28: =IFERROR(VLOOKUP($C28,'MONTHLY DUES 2030'!$C$5:$D$27,2,0),0) -> 0 | M28: =IFERROR(VLOOKUP($C28,'MONTHLY DUES 2031'!$C$5:$D$27,2,0),0) -> 0 | N28: =IFERROR(VLOOKUP($C28,'MONTHLY DUES 2032'!$C$5:$D$27,2,0),0) -> 0
B30: TOTAL | D30: =SUBTOTAL(9,D5:D28) -> 65950 | E30: =SUBTOTAL(9,E5:E28) -> 10800 | F30: =SUBTOTAL(9,F5:F28) -> 16900 | G30: =SUBTOTAL(9,G5:G28) -> 22350 | H30: =SUBTOTAL(9,H5:H28) -> 15900 | I30: =SUBTOTAL(9,I5:I28) -> 0 | J30: =SUBTOTAL(9,J5:J28) -> 0 | K30: =SUBTOTAL(9,K5:K28) -> 0 | ... N30: =SUBTOTAL(9,N5:N28) -> 0
B31: COUNT | D31: =COUNTIF(D5:D29,">0") -> 24 | E31: =COUNTIF(E5:E29,">0") -> 18 | F31: =COUNTIF(F5:F29,">0") -> 20 | G31: =COUNTIF(G5:G29,">0") -> 21 | H31: =COUNTIF(H5:H29,">0") -> 19 | I31: =COUNTIF(I5:I29,">0") -> 0 | J31: =COUNTIF(J5:J29,">0") -> 0 | K31: =COUNTIF(K5:K29,">0") -> 0 | ... N31: =COUNTIF(N5:N29,">0") -> 0

Sheet MONTHLY DUES 2023
B2: MONTHLY DUES - 2023
B3: NO. | C3: ELDER | D3: TOTAL | E3: SHARES | F3: 44927 | G3: 44958 | H3: 44986 | I3: 45017 | J3: 45047 | K3: 45078 | L3: 45108 | M3: 45139 | N3: 45170 | O3: 45200 | P3: 45231 | Q3: 45261
D4: DUES | E4: 50 | F4: ¢ | G4: ¢ | H4: ¢ | I4: ¢ | J4: ¢ | K4: ¢ | L4: ¢ | M4: ¢ | N4: ¢ | O4: ¢ | Q4: ¢
B5: 1 | C5: Fanuel Hagan | D5: =SUM(F5:Q5) -> 600 | E5: =D5/$E$4 -> 12 | F5: 50 | G5: 50 | H5: 50 | I5: 50 | J5: 50 | K5: 50 | L5: 50 | M5: 50 | N5: 50 | O5: 50 | P5: 50 | Q5: 50
B6: 2 | C6: Frederick Wortey Tawiah | D6: =SUM(F6:Q6) -> 600 | E6: =D6/$E$4 -> 12 | F6: 50 | G6: 50 | H6: 50 | I6: 50 | J6: 50 | K6: 50 | L6: 50 | M6: 50 | N6: 50 | O6: 50 | P6: 50 | Q6: 50
B7: 3 | C7: Isaac Darko | D7: =SUM(F7:Q7) -> 600 | E7: =D7/$E$4 -> 12 | F7: 50 | G7: 50 | H7: 50 | I7: 50 | J7: 50 | K7: 50 | L7: 50 | M7: 50 | N7: 50 | O7: 50 | P7: 50 | Q7: 50
B8: 4 | C8: John Ofosuhene Asare | D8: =SUM(F8:Q8) -> 600 | E8: =D8/$E$4 -> 12 | F8: 50 | G8: 50 | H8: 50 | I8: 50 | J8: 50 | K8: 50 | L8: 50 | M8: 50 | N8: 50 | O8: 50 | P8: 50 | Q8: 50
B9: 5 | C9: Johnson Wood | D9: =SUM(F9:Q9) -> 600 | E9: =D9/$E$4 -> 12 | F9: 50 | G9: 50 | H9: 50 | I9: 50 | J9: 50 | K9: 50 | L9: 50 | M9: 50 | N9: 50 | O9: 50 | P9: 50 | Q9: 50
B10: 6 | C10: Jonas Wereko | D10: =SUM(F10:Q10) -> 600 | E10: =D10/$E$4 -> 12 | F10: 50 | G10: 50 | H10: 50 | I10: 50 | J10: 50 | K10: 50 | L10: 50 | M10: 50 | N10: 50 | O10: 50 | P10: 50 | Q10: 50
B11: 7 | C11: Jonathan Danso Siaw | D11: =SUM(F11:Q11) -> 600 | E11: =D11/$E$4 -> 12 | F11: 50 | G11: 50 | H11: 50 | I11: 50 | J11: 50 | K11: 50 | L11: 50 | M11: 50 | N11: 50 | O11: 50 | P11: 50 | Q11: 50
B12: 8 | C12: Joseph Kofi Amanfo | D12: =SUM(F12:Q12) -> 600 | E12: =D12/$E$4 -> 12 | F12: 50 | G12: 50 | H12: 50 | I12: 50 | J12: 50 | K12: 50 | L12: 50 | M12: 50 | N12: 50 | O12: 50 | P12: 50 | Q12: 50
B13: 9 | C13: Justice Kojo Acheampong | D13: =SUM(F13:Q13) -> 600 | E13: =D13/$E$4 -> 12 | F13: 50 | G13: 50 | H13: 50 | I13: 50 | J13: 50 | K13: 50 | L13: 50 | M13: 50 | N13: 50 | O13: 50 | P13: 50 | Q13: 50
B14: 10 | C14: Just-Mark Kwabena Quansah | D14: =SUM(F14:Q14) -> 600 | E14: =D14/$E$4 -> 12 | F14: 50 | G14: 50 | H14: 50 | I14: 50 | J14: 50 | K14: 50 | L14: 50 | M14: 50 | N14: 50 | O14: 50 | P14: 50 | Q14: 50
B15: 11 | C15: Maxwell Ofei Siaw | D15: =SUM(F15:Q15) -> 600 | E15: =D15/$E$4 -> 12 | F15: 50 | G15: 50 | H15: 50 | I15: 50 | J15: 50 | K15: 50 | L15: 50 | M15: 50 | N15: 50 | O15: 50 | P15: 50 | Q15: 50
B16: 12 | C16: Moses Oduro | D16: =SUM(F16:Q16) -> 600 | E16: =D16/$E$4 -> 12 | F16: 50 | G16: 50 | H16: 50 | I16: 50 | J16: 50 | K16: 50 | L16: 50 | M16: 50 | N16: 50 | O16: 50 | P16: 50 | Q16: 50
... B22: 18 | C22: William Kojo Anane | D22: =SUM(F22:Q22) -> 600 | E22: =D22/$E$4 -> 12 | F22: 50 | G22: 50 | H22: 50 | I22: 50 | J22: 50 | K22: 50 | L22: 50 | M22: 50 | N22: 50 | O22: 50 | P22: 50 | Q22: 50
B25: TOTAL | D25: =SUBTOTAL(9,D5:D22) -> 10800 | E25: =SUBTOTAL(9,E5:E22) -> 216 | F25: =SUBTOTAL(9,F5:F22) -> 900 | G25: =SUBTOTAL(9,G5:G22) -> 900 | H25: =SUBTOTAL(9,H5:H22) -> 900 | I25: =SUBTOTAL(9,I5:I22) -> 900 | J25: =SUBTOTAL(9,J5:J22) -> 900 | K25: =SUBTOTAL(9,K5:K22) -> 900 | ... Q25: =SUBTOTAL(9,Q5:Q22) -> 900
B26: COUNT | D26: =COUNTIF(D5:D24,">0") -> 18 | E26: =COUNTIF(E5:E24,">0") -> 18 | F26: =COUNTIF(F5:F24,">0") -> 18 | G26: =COUNTIF(G5:G24,">0") -> 18 | H26: =COUNTIF(H5:H24,">0") -> 18 | I26: =COUNTIF(I5:I24,">0") -> 18 | J26: =COUNTIF(J5:J24,">0") -> 18 | K26: =COUNTIF(K5:K24,">0") -> 18 | ... Q26: =COUNTIF(Q5:Q24,">0") -> 18

Sheet MONTHLY DUES 2024
B2: MONTHLY DUES - 2024
B3: NO. | C3: ELDER | D3: TOTAL | E3: SHARES | F3: 45292 | G3: 45323 | H3: 45352 | I3: 45383 | J3: 45413 | K3: 45444 | L3: 45474 | M3: 45505 | N3: 45536 | O3: 45566 | P3: 45597 | Q3: 45627
D4: DUES | E4: 50 | F4: ¢ | G4: ¢ | H4: ¢ | I4: ¢ | J4: ¢ | K4: ¢ | L4: ¢ | M4: ¢ | N4: ¢ | O4: ¢ | Q4: ¢
B5: 1 | C5: Alex Ackah | D5: =SUM(F5:Q5) -> 900 | E5: =D5/$E$4 -> 18 | F5: 50 | G5: 50 | H5: 50 | I5: 50 | J5: 50 | K5: 50 | L5: 100 | M5: 100 | N5: 100 | O5: 100 | P5: 100 | Q5: 100
B6: 2 | C6: Fanuel Hagan | D6: =SUM(F6:Q6) -> 900 | E6: =D6/$E$4 -> 18 | F6: 50 | G6: 50 | H6: 50 | I6: 50 | J6: 50 | K6: 50 | L6: 100 | M6: 100 | N6: 100 | O6: 100 | P6: 100 | Q6: 100
B7: 3 | C7: Frederick Wortey Tawiah | D7: =SUM(F7:Q7) -> 900 | E7: =D7/$E$4 -> 18 | F7: 50 | G7: 50 | H7: 50 | I7: 50 | J7: 50 | K7: 50 | L7: 100 | M7: 100 | N7: 100 | O7: 100 | P7: 100 | Q7: 100
B8: 4 | C8: Isaac Darko | D8: =SUM(F8:Q8) -> 900 | E8: =D8/$E$4 -> 18 | F8: 50 | G8: 50 | H8: 50 | I8: 50 | J8: 50 | K8: 50 | L8: 100 | M8: 100 | N8: 100 | O8: 100 | P8: 100 | Q8: 100
B9: 5 | C9: Isaac Donkor | D9: =SUM(F9:Q9) -> 900 | E9: =D9/$E$4 -> 18 | F9: 50 | G9: 50 | H9: 50 | I9: 50 | J9: 50 | K9: 50 | L9: 100 | M9: 100 | N9: 100 | O9: 100 | P9: 100 | Q9: 100
B10: 6 | C10: John Ofosuhene Asare | D10: =SUM(F10:Q10) -> 900 | E10: =D10/$E$4 -> 18 | F10: 50 | G10: 50 | H10: 50 | I10: 50 | J10: 50 | K10: 50 | L10: 100 | M10: 100 | N10: 100 | O10: 100 | P10: 100 | Q10: 100
B11: 7 | C11: Johnson Wood | D11: =SUM(F11:Q11) -> 900 | E11: =D11/$E$4 -> 18 | F11: 50 | G11: 50 | H11: 50 | I11: 50 | J11: 50 | K11: 50 | L11: 100 | M11: 100 | N11: 100 | O11: 100 | P11: 100 | Q11: 100
B12: 8 | C12: Jonas Wereko | D12: =SUM(F12:Q12) -> 900 | E12: =D12/$E$4 -> 18 | F12: 50 | G12: 50 | H12: 50 | I12: 50 | J12: 50 | K12: 50 | L12: 100 | M12: 100 | N12: 100 | O12: 100 | P12: 100 | Q12: 100
B13: 9 | C13: Jonathan Danso Siaw | D13: =SUM(F13:Q13) -> 900 | E13: =D13/$E$4 -> 18 | F13: 50 | G13: 50 | H13: 50 | I13: 50 | J13: 50 | K13: 50 | L13: 100 | M13: 100 | N13: 100 | O13: 100 | P13: 100 | Q13: 100
B14: 10 | C14: Justice Kojo Acheampong | D14: =SUM(F14:Q14) -> 900 | E14: =D14/$E$4 -> 18 | F14: 50 | G14: 50 | H14: 50 | I14: 50 | J14: 50 | K14: 50 | L14: 100 | M14: 100 | N14: 100 | O14: 100 | P14: 100 | Q14: 100
B15: 11 | C15: Just-Mark Kwabena Quansah | D15: =SUM(F15:Q15) -> 900 | E15: =D15/$E$4 -> 18 | F15: 50 | G15: 50 | H15: 50 | I15: 50 | J15: 50 | K15: 50 | L15: 100 | M15: 100 | N15: 100 | O15: 100 | P15: 100 | Q15: 100
B16: 12 | C16: Maxwell Ofei Siaw | D16: =SUM(F16:Q16) -> 900 | E16: =D16/$E$4 -> 18 | F16: 50 | G16: 50 | H16: 50 | I16: 50 | J16: 50 | K16: 50 | L16: 100 | M16: 100 | N16: 100 | O16: 100 | P16: 100 | Q16: 100
... B22: 18 | C22: William Kojo Anane | D22: =SUM(F22:Q22) -> 900 | E22: =D22/$E$4 -> 18 | F22: 50 | G22: 50 | H22: 50 | I22: 50 | J22: 50 | K22: 50 | L22: 100 | M22: 100 | N22: 100 | O22: 100 | P22: 100 | Q22: 100
B23: 19 | C23: Joseph Kofi Amanfo | D23: =SUM(F23:Q23) -> 400 | E23: =D23/$E$4 -> 8 | F23: 50 | G23: 50 | H23: 50 | I23: 50 | J23: 50 | K23: 50 | L23: 100
B24: 20 | C24: Peter Kingsford Nkrumah | D24: =SUM(F24:Q24) -> 300 | E24: =D24/$E$4 -> 6 | F24: 50 | G24: 50 | H24: 50 | I24: 50 | J24: 50 | K24: 50
B27: TOTAL | D27: =SUBTOTAL(9,D5:D25) -> 16900 | E27: =SUBTOTAL(9,E5:E25) -> 338 | F27: =SUBTOTAL(9,F5:F25) -> 1000 | G27: =SUBTOTAL(9,G5:G25) -> 1000 | H27: =SUBTOTAL(9,H5:H25) -> 1000 | I27: =SUBTOTAL(9,I5:I25) -> 1000 | J27: =SUBTOTAL(9,J5:J25) -> 1000 | K27: =SUBTOTAL(9,K5:K25) -> 1000 | ... Q27: =SUBTOTAL(9,Q5:Q25) -> 1800
B28: COUNT | D28: =COUNT(D5:D26) -> 20 | E28: =COUNT(E5:E26) -> 20 | F28: =COUNT(F5:F26) -> 20 | G28: =COUNT(G5:G26) -> 20 | H28: =COUNT(H5:H26) -> 20 | I28: =COUNT(I5:I26) -> 20 | J28: =COUNT(J5:J26) -> 20 | K28: =COUNT(K5:K26) -> 20 | ... Q28: =COUNT(Q5:Q26) -> 18

Sheet MONTHLY DUES 2025
B2: MONTHLY DUES - 2025
B3: NO. | C3: ELDER | D3: TOTAL | E3: SHARES | F3: 45658 | G3: 45689 | H3: 45717 | I3: 45748 | J3: 45778 | K3: 45809 | L3: 45839 | M3: 45870 | N3: 45901 | O3: 45931 | P3: 45962 | Q3: 45992
D4: DUES | E4: 50 | F4: ¢ | G4: ¢ | H4: ¢ | I4: ¢ | J4: ¢ | K4: ¢ | L4: ¢ | M4: ¢ | N4: ¢ | O4: ¢ | Q4: ¢
B5: 1 | C5: Alex Ackah | D5: =SUM(F5:Q5) -> 1200 | E5: =D5/$E$4 -> 24 | F5: 100 | G5: 100 | H5: 100 | I5: 100 | J5: 100 | K5: 100 | L5: 100 | M5: 100 | N5: 100 | O5: 100 | P5: 100 | Q5: 100
B6: 2 | C6: Danso Kingsley | D6: =SUM(F6:Q6) -> 1200 | E6: =D6/$E$4 -> 24 | F6: 100 | G6: 100 | H6: 100 | I6: 100 | J6: 100 | K6: 100 | L6: 100 | M6: 100 | N6: 100 | O6: 100 | P6: 100 | Q6: 100
B7: 3 | C7: Fanuel Hagan | D7: =SUM(F7:Q7) -> 1200 | E7: =D7/$E$4 -> 24 | F7: 100 | G7: 100 | H7: 100 | I7: 100 | J7: 100 | K7: 100 | L7: 100 | M7: 100 | N7: 100 | O7: 100 | P7: 100 | Q7: 100
B8: 4 | C8: Frederick Wortey Tawiah | D8: =SUM(F8:Q8) -> 1200 | E8: =D8/$E$4 -> 24 | F8: 100 | G8: 100 | H8: 100 | I8: 100 | J8: 100 | K8: 100 | L8: 100 | M8: 100 | N8: 100 | O8: 100 | P8: 100 | Q8: 100
B9: 5 | C9: Isaac Darko | D9: =SUM(F9:Q9) -> 1200 | E9: =D9/$E$4 -> 24 | F9: 100 | G9: 100 | H9: 100 | I9: 100 | J9: 100 | K9: 100 | L9: 100 | M9: 100 | N9: 100 | O9: 100 | P9: 100 | Q9: 100
B10: 6 | C10: Isaac Donkor | D10: =SUM(F10:Q10) -> 1200 | E10: =D10/$E$4 -> 24 | F10: 100 | G10: 100 | H10: 100 | I10: 100 | J10: 100 | K10: 100 | L10: 100 | M10: 100 | N10: 100 | O10: 100 | P10: 100 | Q10: 100
B11: 7 | C11: John Ofosuhene Asare | D11: =SUM(F11:Q11) -> 1200 | E11: =D11/$E$4 -> 24 | F11: 100 | G11: 100 | H11: 100 | I11: 100 | J11: 100 | K11: 100 | L11: 100 | M11: 100 | N11: 100 | O11: 100 | P11: 100 | Q11: 100
B12: 8 | C12: Johnson Wood | D12: =SUM(F12:Q12) -> 1200 | E12: =D12/$E$4 -> 24 | F12: 100 | G12: 100 | H12: 100 | I12: 100 | J12: 100 | K12: 100 | L12: 100 | M12: 100 | N12: 100 | O12: 100 | P12: 100 | Q12: 100
B13: 9 | C13: Jonas Wereko | D13: =SUM(F13:Q13) -> 1200 | E13: =D13/$E$4 -> 24 | F13: 100 | G13: 100 | H13: 100 | I13: 100 | J13: 100 | K13: 100 | L13: 100 | M13: 100 | N13: 100 | O13: 100 | P13: 100 | Q13: 100
B14: 10 | C14: Jonathan Danso Siaw | D14: =SUM(F14:Q14) -> 1200 | E14: =D14/$E$4 -> 24 | F14: 100 | G14: 100 | H14: 100 | I14: 100 | J14: 100 | K14: 100 | L14: 100 | M14: 100 | N14: 100 | O14: 100 | P14: 100 | Q14: 100
B15: 11 | C15: Just-Mark Kwabena Quansah | D15: =SUM(F15:Q15) -> 1200 | E15: =D15/$E$4 -> 24 | F15: 100 | G15: 100 | H15: 100 | I15: 100 | J15: 100 | K15: 100 | L15: 100 | M15: 100 | N15: 100 | O15: 100 | P15: 100 | Q15: 100
B16: 12 | C16: Maxwell Ofei Siaw | D16: =SUM(F16:Q16) -> 1200 | E16: =D16/$E$4 -> 24 | F16: 100 | G16: 100 | H16: 100 | I16: 100 | J16: 100 | K16: 100 | L16: 100 | M16: 100 | N16: 100 | O16: 100 | P16: 100 | Q16: 100
... B22: 18 | C22: Justice Kojo Acheampong | D22: =SUM(F22:Q22) -> 1200 | E22: =D22/$E$4 -> 24 | F22: 100 | G22: 100 | H22: 100 | I22: 100 | J22: 100 | K22: 100 | L22: 100 | M22: 100 | N22: 100 | O22: 100 | P22: 100 | Q22: 100
B23: 19 | C23: John Darbo | D23: =SUM(F23:Q23) -> 350 | E23: =D23/$E$4 -> 7 | F23: 100 | G23: 100 | H23: 100 | I23: 50
B24: 20 | C24: George Yeboah | D24: =SUM(F24:Q24) -> 200 | E24: =D24/$E$4 -> 4 | F24: 100 | G24: 100
B25: 21 | C25: Samuel Yaw Nkansah | D25: =SUM(F25:Q25) -> 200 | E25: =D25/$E$4 -> 4 | F25: 100 | G25: 100
B28: TOTAL | D28: =SUBTOTAL(9,D5:D27) -> 22350 | E28: =SUBTOTAL(9,E5:E27) -> 447 | F28: =SUBTOTAL(9,F5:F27) -> 2100 | G28: =SUBTOTAL(9,G5:G27) -> 2100 | H28: =SUBTOTAL(9,H5:H27) -> 1900 | I28: =SUBTOTAL(9,I5:I27) -> 1850 | J28: =SUBTOTAL(9,J5:J27) -> 1800 | K28: =SUBTOTAL(9,K5:K27) -> 1800 | ... Q28: =SUBTOTAL(9,Q5:Q27) -> 1800
B29: COUNT | D29: =COUNTIF(D5:D27,">0") -> 21 | E29: =COUNTIF(E5:E27,">0") -> 21 | F29: =COUNTIF(F5:F27,">0") -> 21 | G29: =COUNTIF(G5:G27,">0") -> 21 | H29: =COUNTIF(H5:H27,">0") -> 19 | I29: =COUNTIF(I5:I27,">0") -> 19 | J29: =COUNTIF(J5:J27,">0") -> 18 | K29: =COUNTIF(K5:K27,">0") -> 18 | ... Q29: =COUNTIF(Q5:Q27,">0") -> 18

Sheet MONTHLY DUES 2026
B2: MONTHLY DUES - 2026
B3: NO. | C3: ELDER | D3: TOTAL | E3: SHARES | F3: 46023 | G3: 46054 | H3: 46082 | I3: 46113 | J3: 46143 | K3: 46174 | L3: 46204 | M3: 46235 | N3: 46266 | O3: 46296 | P3: 46327 | Q3: 46357
D4: DUES | E4: 50 | F4: ¢ | G4: ¢ | H4: ¢ | I4: ¢ | J4: ¢ | K4: ¢ | L4: ¢ | M4: ¢ | N4: ¢ | O4: ¢ | Q4: ¢
B5: 1 | C5: Isaac Darko | D5: =SUM(F5:Q5) -> 1200 | E5: =D5/$E$4 -> 24 | F5: 100 | G5: 100 | H5: 100 | I5: 100 | J5: 100 | K5: 100 | L5: 100 | M5: 100 | N5: 100 | O5: 100 | P5: 100 | Q5: 100
B6: 2 | C6: Isaac Donkor | D6: =SUM(F6:Q6) -> 1200 | E6: =D6/$E$4 -> 24 | F6: 100 | G6: 100 | H6: 100 | I6: 100 | J6: 100 | K6: 100 | L6: 100 | M6: 100 | N6: 100 | O6: 100 | P6: 100 | Q6: 100
B7: 3 | C7: Jonathan Danso Siaw | D7: =SUM(F7:Q7) -> 1200 | E7: =D7/$E$4 -> 24 | F7: 100 | G7: 100 | H7: 100 | I7: 100 | J7: 100 | K7: 100 | L7: 100 | M7: 100 | N7: 100 | O7: 100 | P7: 100 | Q7: 100
B8: 4 | C8: Moses Oduro | D8: =SUM(F8:Q8) -> 1200 | E8: =D8/$E$4 -> 24 | F8: 100 | G8: 100 | H8: 100 | I8: 100 | J8: 100 | K8: 100 | L8: 100 | M8: 100 | N8: 100 | O8: 100 | P8: 100 | Q8: 100
B9: 5 | C9: William Kojo Anane | D9: =SUM(F9:Q9) -> 1200 | E9: =D9/$E$4 -> 24 | F9: 100 | G9: 100 | H9: 100 | I9: 100 | J9: 100 | K9: 100 | L9: 100 | M9: 100 | N9: 100 | O9: 100 | P9: 100 | Q9: 100
B10: 6 | C10: Maxwell Ofei Siaw | D10: =SUM(F10:Q10) -> 1000 | E10: =D10/$E$4 -> 20 | F10: 100 | G10: 100 | H10: 100 | I10: 100 | J10: 100 | K10: 100 | L10: 100 | M10: 100 | N10: 100 | O10: 100
B11: 7 | C11: Vincent Agamatey | D11: =SUM(F11:Q11) -> 1000 | E11: =D11/$E$4 -> 20 | F11: 100 | G11: 100 | H11: 100 | I11: 100 | J11: 100 | K11: 100 | L11: 100 | M11: 100 | N11: 100 | O11: 100
B12: 8 | C12: Alex Ackah | D12: =SUM(F12:Q12) -> 900 | E12: =D12/$E$4 -> 18 | F12: 100 | G12: 100 | H12: 100 | I12: 100 | J12: 100 | K12: 100 | L12: 100 | M12: 100 | N12: 100
B13: 9 | C13: John Aidoo | D13: =SUM(F13:Q13) -> 900 | E13: =D13/$E$4 -> 18 | F13: 100 | G13: 100 | H13: 100 | I13: 100 | J13: 100 | K13: 100 | L13: 100 | M13: 100 | N13: 100
B14: 10 | C14: Jonas Wereko | D14: =SUM(F14:Q14) -> 900 | E14: =D14/$E$4 -> 18 | F14: 100 | G14: 100 | H14: 100 | I14: 100 | J14: 100 | K14: 100 | L14: 100 | M14: 100 | N14: 100
B15: 11 | C15: Johnson Wood | D15: =SUM(F15:Q15) -> 800 | E15: =D15/$E$4 -> 16 | F15: 100 | G15: 100 | H15: 100 | I15: 100 | J15: 100 | K15: 100 | L15: 100 | M15: 100
B16: 12 | C16: Osei Kwame | D16: =SUM(F16:Q16) -> 800 | E16: =D16/$E$4 -> 16 | F16: 100 | G16: 100 | H16: 100 | I16: 100 | J16: 100 | K16: 100 | L16: 100 | M16: 100
B17: 13 | C17: Fanuel Hagan | D17: =SUM(F17:Q17) -> 700 | E17: =D17/$E$4 -> 14 | F17: 100 | G17: 100 | H17: 100 | I17: 100 | J17: 100 | K17: 100 | L17: 100
B18: 14 | C18: Frederick Wortey Tawiah | D18: =SUM(F18:Q18) -> 700 | E18: =D18/$E$4 -> 14 | F18: 100 | G18: 100 | H18: 100 | I18: 100 | J18: 100 | K18: 100 | L18: 100
B19: 15 | C19: John Ofosuhene Asare | D19: =SUM(F19:Q19) -> 700 | E19: =D19/$E$4 -> 14 | F19: 100 | G19: 100 | H19: 100 | I19: 100 | J19: 100 | K19: 100 | L19: 100
B20: 16 | C20: Prince Asante Ahwireng | D20: =SUM(F20:Q20) -> 600 | E20: =D20/$E$4 -> 12 | F20: 100 | G20: 100 | H20: 100 | I20: 100 | J20: 100 | K20: 100
B21: 17 | C21: Danso Kingsley | D21: =SUM(F21:Q21) -> 300 | E21: =D21/$E$4 -> 6 | F21: 100 | G21: 100 | H21: 100
B22: 18 | C22: Just-Mark Kwabena Quansah | D22: =SUM(F22:Q22) -> 300 | E22: =D22/$E$4 -> 6 | F22: 100 | G22: 100 | H22: 100
B23: 19 | C23: Justice Kojo Acheampong | D23: =SUM(F23:Q23) -> 300 | E23: =D23/$E$4 -> 6 | F23: 100 | G23: 100 | H23: 100
B26: TOTAL | D26: =SUBTOTAL(9,D5:D25) -> 15900 | E26: =SUBTOTAL(9,E5:E25) -> 318 | F26: =SUBTOTAL(9,F5:F25) -> 1900 | G26: =SUBTOTAL(9,G5:G25) -> 1900 | H26: =SUBTOTAL(9,H5:H25) -> 1900 | I26: =SUBTOTAL(9,I5:I25) -> 1600 | J26: =SUBTOTAL(9,J5:J25) -> 1600 | K26: =SUBTOTAL(9,K5:K25) -> 1600 | ... Q26: =SUBTOTAL(9,Q5:Q25) -> 500
B27: COUNT | D27: =COUNTIF(D5:D25,">0") -> 19 | E27: =COUNTIF(E5:E25,">0") -> 19 | F27: =COUNTIF(F5:F25,">0") -> 19 | G27: =COUNTIF(G5:G25,">0") -> 19 | H27: =COUNTIF(H5:H25,">0") -> 19 | I27: =COUNTIF(I5:I25,">0") -> 16 | J27: =COUNTIF(J5:J25,">0") -> 16 | K27: =COUNTIF(K5:K25,">0") -> 16 | ... Q27: =COUNTIF(Q5:Q25,">0") -> 5

Sheet MONTHLY DUES 2027
B2: MONTHLY DUES - 2027
B3: NO. | C3: ELDER | D3: TOTAL | E3: COUNT | F3: 46388 | G3: 46419 | H3: 46447 | I3: 46478 | J3: 46508 | K3: 46539 | L3: 46569 | M3: 46600 | N3: 46631 | O3: 46661 | P3: 46692 | Q3: 46722
D4: DUES | F4: ¢ | G4: ¢ | H4: ¢ | I4: ¢ | J4: ¢ | K4: ¢ | L4: ¢ | M4: ¢ | N4: ¢ | O4: ¢ | Q4: ¢
B5: 1 | D5: =SUM(F5:Q5) -> 0 | E5: =COUNT(F5:Q5) -> 0
B6: 2 | D6: =SUM(F6:Q6) -> 0 | E6: =COUNT(F6:Q6) -> 0
B7: 3 | D7: =SUM(F7:Q7) -> 0 | E7: =COUNT(F7:Q7) -> 0
B8: 4 | D8: =SUM(F8:Q8) -> 0 | E8: =COUNT(F8:Q8) -> 0
B9: 5 | D9: =SUM(F9:Q9) -> 0 | E9: =COUNT(F9:Q9) -> 0
B10: 6 | D10: =SUM(F10:Q10) -> 0 | E10: =COUNT(F10:Q10) -> 0
B11: 7 | D11: =SUM(F11:Q11) -> 0 | E11: =COUNT(F11:Q11) -> 0
B12: 8 | D12: =SUM(F12:Q12) -> 0 | E12: =COUNT(F12:Q12) -> 0
B13: 9 | D13: =SUM(F13:Q13) -> 0 | E13: =COUNT(F13:Q13) -> 0
B14: 10 | D14: =SUM(F14:Q14) -> 0 | E14: =COUNT(F14:Q14) -> 0
B15: 11 | D15: =SUM(F15:Q15) -> 0 | E15: =COUNT(F15:Q15) -> 0
B16: 12 | D16: =SUM(F16:Q16) -> 0 | E16: =COUNT(F16:Q16) -> 0
... B27: 23 | D27: =SUM(F27:Q27) -> 0 | E27: =COUNT(F27:Q27) -> 0
B30: TOTAL | D30: =SUBTOTAL(9,D5:D29) -> 0 | E30: =SUBTOTAL(9,E5:E29) -> 0 | F30: =SUBTOTAL(9,F5:F29) -> 0 | G30: =SUBTOTAL(9,G5:G29) -> 0 | H30: =SUBTOTAL(9,H5:H29) -> 0 | I30: =SUBTOTAL(9,I5:I29) -> 0 | J30: =SUBTOTAL(9,J5:J29) -> 0 | K30: =SUBTOTAL(9,K5:K29) -> 0 | ... Q30: =SUBTOTAL(9,Q5:Q29) -> 0
B31: COUNT | D31: =COUNTIF(D5:D29,">0") -> 0 | E31: =COUNTIF(E5:E29,">0") -> 0 | F31: =COUNTIF(F5:F29,">0") -> 0 | G31: =COUNTIF(G5:G29,">0") -> 0 | H31: =COUNTIF(H5:H29,">0") -> 0 | I31: =COUNTIF(I5:I29,">0") -> 0 | J31: =COUNTIF(J5:J29,">0") -> 0 | K31: =COUNTIF(K5:K29,">0") -> 0 | ... Q31: =COUNTIF(Q5:Q29,">0") -> 0

Sheet MONTHLY DUES 2028
B2: MONTHLY DUES - 2028
B3: NO. | C3: ELDER | D3: TOTAL | E3: COUNT | F3: 46753 | G3: 46784 | H3: 46813 | I3: 46844 | J3: 46874 | K3: 46905 | L3: 46935 | M3: 46966 | N3: 46997 | O3: 47027 | P3: 47058 | Q3: 47088
D4: DUES | F4: ¢ | G4: ¢ | H4: ¢ | I4: ¢ | J4: ¢ | K4: ¢ | L4: ¢ | M4: ¢ | N4: ¢ | O4: ¢ | Q4: ¢
B5: 1 | D5: =SUM(F5:Q5) -> 0 | E5: =COUNT(F5:Q5) -> 0
B6: 2 | D6: =SUM(F6:Q6) -> 0 | E6: =COUNT(F6:Q6) -> 0
B7: 3 | D7: =SUM(F7:Q7) -> 0 | E7: =COUNT(F7:Q7) -> 0
B8: 4 | D8: =SUM(F8:Q8) -> 0 | E8: =COUNT(F8:Q8) -> 0
B9: 5 | D9: =SUM(F9:Q9) -> 0 | E9: =COUNT(F9:Q9) -> 0
B10: 6 | D10: =SUM(F10:Q10) -> 0 | E10: =COUNT(F10:Q10) -> 0
B11: 7 | D11: =SUM(F11:Q11) -> 0 | E11: =COUNT(F11:Q11) -> 0
B12: 8 | D12: =SUM(F12:Q12) -> 0 | E12: =COUNT(F12:Q12) -> 0
B13: 9 | D13: =SUM(F13:Q13) -> 0 | E13: =COUNT(F13:Q13) -> 0
B14: 10 | D14: =SUM(F14:Q14) -> 0 | E14: =COUNT(F14:Q14) -> 0
B15: 11 | D15: =SUM(F15:Q15) -> 0 | E15: =COUNT(F15:Q15) -> 0
B16: 12 | D16: =SUM(F16:Q16) -> 0 | E16: =COUNT(F16:Q16) -> 0
... B27: 23 | D27: =SUM(F27:Q27) -> 0 | E27: =COUNT(F27:Q27) -> 0
B30: TOTAL | D30: =SUBTOTAL(9,D5:D29) -> 0 | E30: =SUBTOTAL(9,E5:E29) -> 0 | F30: =SUBTOTAL(9,F5:F29) -> 0 | G30: =SUBTOTAL(9,G5:G29) -> 0 | H30: =SUBTOTAL(9,H5:H29) -> 0 | I30: =SUBTOTAL(9,I5:I29) -> 0 | J30: =SUBTOTAL(9,J5:J29) -> 0 | K30: =SUBTOTAL(9,K5:K29) -> 0 | ... Q30: =SUBTOTAL(9,Q5:Q29) -> 0
B31: COUNT | D31: =COUNTIF(D5:D29,">0") -> 0 | E31: =COUNTIF(E5:E29,">0") -> 0 | F31: =COUNTIF(F5:F29,">0") -> 0 | G31: =COUNTIF(G5:G29,">0") -> 0 | H31: =COUNTIF(H5:H29,">0") -> 0 | I31: =COUNTIF(I5:I29,">0") -> 0 | J31: =COUNTIF(J5:J29,">0") -> 0 | K31: =COUNTIF(K5:K29,">0") -> 0 | ... Q31: =COUNTIF(Q5:Q29,">0") -> 0

Sheet MONTHLY DUES 2029
B2: MONTHLY DUES - 2029
B3: NO. | C3: ELDER | D3: TOTAL | E3: COUNT | F3: 47119 | G3: 47150 | H3: 47178 | I3: 47209 | J3: 47239 | K3: 47270 | L3: 47300 | M3: 47331 | N3: 47362 | O3: 47392 | P3: 47423 | Q3: 47453
D4: DUES | F4: ¢ | G4: ¢ | H4: ¢ | I4: ¢ | J4: ¢ | K4: ¢ | L4: ¢ | M4: ¢ | N4: ¢ | O4: ¢ | Q4: ¢
B5: 1 | D5: =SUM(F5:Q5) -> 0 | E5: =COUNT(F5:Q5) -> 0
B6: 2 | D6: =SUM(F6:Q6) -> 0 | E6: =COUNT(F6:Q6) -> 0
B7: 3 | D7: =SUM(F7:Q7) -> 0 | E7: =COUNT(F7:Q7) -> 0
B8: 4 | D8: =SUM(F8:Q8) -> 0 | E8: =COUNT(F8:Q8) -> 0
B9: 5 | D9: =SUM(F9:Q9) -> 0 | E9: =COUNT(F9:Q9) -> 0
B10: 6 | D10: =SUM(F10:Q10) -> 0 | E10: =COUNT(F10:Q10) -> 0
B11: 7 | D11: =SUM(F11:Q11) -> 0 | E11: =COUNT(F11:Q11) -> 0
B12: 8 | D12: =SUM(F12:Q12) -> 0 | E12: =COUNT(F12:Q12) -> 0
B13: 9 | D13: =SUM(F13:Q13) -> 0 | E13: =COUNT(F13:Q13) -> 0
B14: 10 | D14: =SUM(F14:Q14) -> 0 | E14: =COUNT(F14:Q14) -> 0
B15: 11 | D15: =SUM(F15:Q15) -> 0 | E15: =COUNT(F15:Q15) -> 0
B16: 12 | D16: =SUM(F16:Q16) -> 0 | E16: =COUNT(F16:Q16) -> 0
... B27: 23 | D27: =SUM(F27:Q27) -> 0 | E27: =COUNT(F27:Q27) -> 0
B30: TOTAL | D30: =SUBTOTAL(9,D5:D29) -> 0 | E30: =SUBTOTAL(9,E5:E29) -> 0 | F30: =SUBTOTAL(9,F5:F29) -> 0 | G30: =SUBTOTAL(9,G5:G29) -> 0 | H30: =SUBTOTAL(9,H5:H29) -> 0 | I30: =SUBTOTAL(9,I5:I29) -> 0 | J30: =SUBTOTAL(9,J5:J29) -> 0 | K30: =SUBTOTAL(9,K5:K29) -> 0 | ... Q30: =SUBTOTAL(9,Q5:Q29) -> 0
B31: COUNT | D31: =COUNTIF(D5:D29,">0") -> 0 | E31: =COUNTIF(E5:E29,">0") -> 0 | F31: =COUNTIF(F5:F29,">0") -> 0 | G31: =COUNTIF(G5:G29,">0") -> 0 | H31: =COUNTIF(H5:H29,">0") -> 0 | I31: =COUNTIF(I5:I29,">0") -> 0 | J31: =COUNTIF(J5:J29,">0") -> 0 | K31: =COUNTIF(K5:K29,">0") -> 0 | ... Q31: =COUNTIF(Q5:Q29,">0") -> 0

Sheet MONTHLY DUES 2030
B2: MONTHLY DUES - 2030
B3: NO. | C3: ELDER | D3: TOTAL | E3: COUNT | F3: 47484 | G3: 47515 | H3: 47543 | I3: 47574 | J3: 47604 | K3: 47635 | L3: 47665 | M3: 47696 | N3: 47727 | O3: 47757 | P3: 47788 | Q3: 47818
D4: DUES | F4: ¢ | G4: ¢ | H4: ¢ | I4: ¢ | J4: ¢ | K4: ¢ | L4: ¢ | M4: ¢ | N4: ¢ | O4: ¢ | Q4: ¢
B5: 1 | D5: =SUM(F5:Q5) -> 0 | E5: =COUNT(F5:Q5) -> 0
B6: 2 | D6: =SUM(F6:Q6) -> 0 | E6: =COUNT(F6:Q6) -> 0
B7: 3 | D7: =SUM(F7:Q7) -> 0 | E7: =COUNT(F7:Q7) -> 0
B8: 4 | D8: =SUM(F8:Q8) -> 0 | E8: =COUNT(F8:Q8) -> 0
B9: 5 | D9: =SUM(F9:Q9) -> 0 | E9: =COUNT(F9:Q9) -> 0
B10: 6 | D10: =SUM(F10:Q10) -> 0 | E10: =COUNT(F10:Q10) -> 0
B11: 7 | D11: =SUM(F11:Q11) -> 0 | E11: =COUNT(F11:Q11) -> 0
B12: 8 | D12: =SUM(F12:Q12) -> 0 | E12: =COUNT(F12:Q12) -> 0
B13: 9 | D13: =SUM(F13:Q13) -> 0 | E13: =COUNT(F13:Q13) -> 0
B14: 10 | D14: =SUM(F14:Q14) -> 0 | E14: =COUNT(F14:Q14) -> 0
B15: 11 | D15: =SUM(F15:Q15) -> 0 | E15: =COUNT(F15:Q15) -> 0
B16: 12 | D16: =SUM(F16:Q16) -> 0 | E16: =COUNT(F16:Q16) -> 0
... B27: 23 | D27: =SUM(F27:Q27) -> 0 | E27: =COUNT(F27:Q27) -> 0
B30: TOTAL | D30: =SUBTOTAL(9,D5:D29) -> 0 | E30: =SUBTOTAL(9,E5:E29) -> 0 | F30: =SUBTOTAL(9,F5:F29) -> 0 | G30: =SUBTOTAL(9,G5:G29) -> 0 | H30: =SUBTOTAL(9,H5:H29) -> 0 | I30: =SUBTOTAL(9,I5:I29) -> 0 | J30: =SUBTOTAL(9,J5:J29) -> 0 | K30: =SUBTOTAL(9,K5:K29) -> 0 | ... Q30: =SUBTOTAL(9,Q5:Q29) -> 0
B31: COUNT | D31: =COUNTIF(D5:D29,">0") -> 0 | E31: =COUNTIF(E5:E29,">0") -> 0 | F31: =COUNTIF(F5:F29,">0") -> 0 | G31: =COUNTIF(G5:G29,">0") -> 0 | H31: =COUNTIF(H5:H29,">0") -> 0 | I31: =COUNTIF(I5:I29,">0") -> 0 | J31: =COUNTIF(J5:J29,">0") -> 0 | K31: =COUNTIF(K5:K29,">0") -> 0 | ... Q31: =COUNTIF(Q5:Q29,">0") -> 0

Sheet MONTHLY DUES 2031
B2: MONTHLY DUES - 2031
B3: NO. | C3: ELDER | D3: TOTAL | E3: COUNT | F3: 47849 | G3: 47880 | H3: 47908 | I3: 47939 | J3: 47969 | K3: 48000 | L3: 48030 | M3: 48061 | N3: 48092 | O3: 48122 | P3: 48153 | Q3: 48183
D4: DUES | F4: ¢ | G4: ¢ | H4: ¢ | I4: ¢ | J4: ¢ | K4: ¢ | L4: ¢ | M4: ¢ | N4: ¢ | O4: ¢ | Q4: ¢
B5: 1 | D5: =SUM(F5:Q5) -> 0 | E5: =COUNT(F5:Q5) -> 0
B6: 2 | D6: =SUM(F6:Q6) -> 0 | E6: =COUNT(F6:Q6) -> 0
B7: 3 | D7: =SUM(F7:Q7) -> 0 | E7: =COUNT(F7:Q7) -> 0
B8: 4 | D8: =SUM(F8:Q8) -> 0 | E8: =COUNT(F8:Q8) -> 0
B9: 5 | D9: =SUM(F9:Q9) -> 0 | E9: =COUNT(F9:Q9) -> 0
B10: 6 | D10: =SUM(F10:Q10) -> 0 | E10: =COUNT(F10:Q10) -> 0
B11: 7 | D11: =SUM(F11:Q11) -> 0 | E11: =COUNT(F11:Q11) -> 0
B12: 8 | D12: =SUM(F12:Q12) -> 0 | E12: =COUNT(F12:Q12) -> 0
B13: 9 | D13: =SUM(F13:Q13) -> 0 | E13: =COUNT(F13:Q13) -> 0
B14: 10 | D14: =SUM(F14:Q14) -> 0 | E14: =COUNT(F14:Q14) -> 0
B15: 11 | D15: =SUM(F15:Q15) -> 0 | E15: =COUNT(F15:Q15) -> 0
B16: 12 | D16: =SUM(F16:Q16) -> 0 | E16: =COUNT(F16:Q16) -> 0
... B23: 19 | D23: =SUM(F23:Q23) -> 0 | E23: =COUNT(F23:Q23) -> 0
B24: 20 | D24: =SUM(F24:Q24) -> 0
B25: 21 | D25: =SUM(F25:Q25) -> 0
B26: 22 | D26: =SUM(F26:Q26) -> 0
B27: 23 | D27: =SUM(F27:Q27) -> 0
B30: TOTAL | D30: =SUBTOTAL(9,D5:D29) -> 0 | E30: =SUBTOTAL(9,E5:E29) -> 0 | F30: =SUBTOTAL(9,F5:F29) -> 0 | G30: =SUBTOTAL(9,G5:G29) -> 0 | H30: =SUBTOTAL(9,H5:H29) -> 0 | I30: =SUBTOTAL(9,I5:I29) -> 0 | J30: =SUBTOTAL(9,J5:J29) -> 0 | K30: =SUBTOTAL(9,K5:K29) -> 0 | ... Q30: =SUBTOTAL(9,Q5:Q29) -> 0
B31: COUNT | D31: =COUNTIF(D5:D29,">0") -> 0 | E31: =COUNTIF(E5:E29,">0") -> 0 | F31: =COUNTIF(F5:F29,">0") -> 0 | G31: =COUNTIF(G5:G29,">0") -> 0 | H31: =COUNTIF(H5:H29,">0") -> 0 | I31: =COUNTIF(I5:I29,">0") -> 0 | J31: =COUNTIF(J5:J29,">0") -> 0 | K31: =COUNTIF(K5:K29,">0") -> 0 | ... Q31: =COUNTIF(Q5:Q29,">0") -> 0

Sheet MONTHLY DUES 2032
B2: MONTHLY DUES - 2032
B3: NO. | C3: ELDER | D3: TOTAL | E3: COUNT | F3: 48214 | G3: 48245 | H3: 48274 | I3: 48305 | J3: 48335 | K3: 48366 | L3: 48396 | M3: 48427 | N3: 48458 | O3: 48488 | P3: 48519 | Q3: 48549
D4: DUES | F4: ¢ | G4: ¢ | H4: ¢ | I4: ¢ | J4: ¢ | K4: ¢ | L4: ¢ | M4: ¢ | N4: ¢ | O4: ¢ | Q4: ¢
B5: 1 | D5: =SUM(F5:Q5) -> 0 | E5: =COUNT(F5:Q5) -> 0
B6: 2 | D6: =SUM(F6:Q6) -> 0 | E6: =COUNT(F6:Q6) -> 0
B7: 3 | D7: =SUM(F7:Q7) -> 0 | E7: =COUNT(F7:Q7) -> 0
B8: 4 | D8: =SUM(F8:Q8) -> 0 | E8: =COUNT(F8:Q8) -> 0
B9: 5 | D9: =SUM(F9:Q9) -> 0 | E9: =COUNT(F9:Q9) -> 0
B10: 6 | D10: =SUM(F10:Q10) -> 0 | E10: =COUNT(F10:Q10) -> 0
B11: 7 | D11: =SUM(F11:Q11) -> 0 | E11: =COUNT(F11:Q11) -> 0
B12: 8 | D12: =SUM(F12:Q12) -> 0 | E12: =COUNT(F12:Q12) -> 0
B13: 9 | D13: =SUM(F13:Q13) -> 0 | E13: =COUNT(F13:Q13) -> 0
B14: 10 | D14: =SUM(F14:Q14) -> 0 | E14: =COUNT(F14:Q14) -> 0
B15: 11 | D15: =SUM(F15:Q15) -> 0 | E15: =COUNT(F15:Q15) -> 0
B16: 12 | D16: =SUM(F16:Q16) -> 0 | E16: =COUNT(F16:Q16) -> 0
... B27: 23 | D27: =SUM(F27:Q27) -> 0 | E27: =COUNT(F27:Q27) -> 0
B30: TOTAL | D30: =SUBTOTAL(9,D5:D29) -> 0 | E30: =SUBTOTAL(9,E5:E29) -> 0 | F30: =SUBTOTAL(9,F5:F29) -> 0 | G30: =SUBTOTAL(9,G5:G29) -> 0 | H30: =SUBTOTAL(9,H5:H29) -> 0 | I30: =SUBTOTAL(9,I5:I29) -> 0 | J30: =SUBTOTAL(9,J5:J29) -> 0 | K30: =SUBTOTAL(9,K5:K29) -> 0 | ... Q30: =SUBTOTAL(9,Q5:Q29) -> 0
B31: COUNT | D31: =COUNTIF(D5:D29,">0") -> 0 | E31: =COUNTIF(E5:E29,">0") -> 0 | F31: =COUNTIF(F5:F29,">0") -> 0 | G31: =COUNTIF(G5:G29,">0") -> 0 | H31: =COUNTIF(H5:H29,">0") -> 0 | I31: =COUNTIF(I5:I29,">0") -> 0 | J31: =COUNTIF(J5:J29,">0") -> 0 | K31: =COUNTIF(K5:K29,">0") -> 0 | ... Q31: =COUNTIF(Q5:Q29,">0") -> 0

Sheet  SPECIAL LEVY FEES
B2: SPECIAL LEVY FEES
A4: ` | B4: NO. | C4: NAME | D4: TOTAL | E4: ELD. ISAAC DARKO | F4: ELD. SAMUEL NKANSAH | G4: ELD. SAMUEL NKANSAH | H4: ELD. JOHN OFOSUHENE ASARE | I4: ELD JONATHAN DANSO SIAW | J4: ELD PRINCE AHWIREN ASANTE
B5: 1 | C5: Alex Ackah | D5: =SUM(E5:N5) -> 700 | E5: 0 | F5: 0 | G5: 200 | H5: 200 | I5: 200 | J5: 100
B6: 2 | C6: Danso Kingsley | D6: =SUM(E6:N6) -> 100 | E6: 0 | F6: 0 | G6: 0 | H6: 0 | I6: 0 | J6: 100
B7: 3 | C7: Fanuel Hagan | D7: =SUM(E7:N7) -> 1000 | E7: 200 | F7: 100 | G7: 200 | H7: 200 | I7: 200 | J7: 100
B8: 4 | C8: Frederick Wortey Tawiah | D8: =SUM(E8:N8) -> 1000 | E8: 200 | F8: 100 | G8: 200 | H8: 200 | I8: 200 | J8: 100
B9: 5 | C9: George Yeboah | D9: =SUM(E9:N9) -> 100 | E9: 0 | F9: 0 | G9: 0 | H9: 0 | I9: 0 | J9: 100
B10: 6 | C10: Isaac Darko | D10: =SUM(E10:N10) -> 800 | E10: 0 | F10: 100 | G10: 200 | H10: 200 | I10: 200 | J10: 100
B11: 7 | C11: Isaac Donkor | D11: =SUM(E11:N11) -> 100 | E11: 0 | F11: 0 | G11: 0 | H11: 0 | I11: 0 | J11: 100
B12: 8 | C12: John Aidoo | D12: =SUM(E12:N12) -> 0 | E12: 0 | F12: 0 | G12: 0 | H12: 0 | I12: 0 | J12: 0
B13: 9 | C13: John Darbo | D13: =SUM(E13:N13) -> 100 | E13: 0 | F13: 0 | G13: 0 | H13: 0 | I13: 0 | J13: 100
B14: 10 | C14: John Ofosuhene Asare | D14: =SUM(E14:N14) -> 800 | E14: 200 | F14: 100 | G14: 200 | H14: 0 | I14: 200 | J14: 100
B15: 11 | C15: Johnson Wood | D15: =SUM(E15:N15) -> 1000 | E15: 200 | F15: 100 | G15: 200 | H15: 200 | I15: 200 | J15: 100
B16: 12 | C16: Jonas Wereko | D16: =SUM(E16:N16) -> 1000 | E16: 200 | F16: 100 | G16: 200 | H16: 200 | I16: 200 | J16: 100
... B28: 24 | C28: William Kojo Anane | D28: =SUM(E28:N28) -> 1000 | E28: 200 | F28: 100 | G28: 200 | H28: 200 | I28: 200 | J28: 100
B30: TOTAL | D30: =SUBTOTAL(9,D5:D28) -> 18100 | E30: =SUBTOTAL(9,E5:E28) -> 3400 | F30: =SUBTOTAL(9,F5:F28) -> 1700 | G30: =SUBTOTAL(9,G5:G28) -> 3600 | H30: =SUBTOTAL(9,H5:H28) -> 3600 | I30: =SUBTOTAL(9,I5:I28) -> 3600 | J30: =SUBTOTAL(9,J5:J28) -> 2200 | K30: =SUBTOTAL(9,K5:K28) -> 0 | ... N30: =SUBTOTAL(9,N5:N28) -> 0
B31: TOTAL MEMBERS PAID | D31: =COUNTIF(D5:D28,">0") -> 23 | E31: =COUNTIF(E5:E28,">0") -> 17 | F31: =COUNTIF(F5:F28,">0") -> 17 | G31: =COUNTIF(G5:G28,">0") -> 18 | H31: =COUNTIF(H5:H28,">0") -> 18 | I31: =COUNTIF(I5:I28,">0") -> 18 | J31: =COUNTIF(J5:J28,">0") -> 22 | K31: =COUNTIF(K5:K28,">0") -> 0 | ... N31: =COUNTIF(N5:N28,">0") -> 0
B32: TOTAL MEMBERS NOT PAID | D32: =COUNTIF(D5:D28,0) -> 1 | E32: =COUNTIF(E5:E28,0) -> 7 | F32: =COUNTIF(F5:F28,0) -> 7 | G32: =COUNTIF(G5:G28,0) -> 6 | H32: =COUNTIF(H5:H28,0) -> 6 | I32: =COUNTIF(I5:I28,0) -> 6 | J32: =COUNTIF(J5:J28,0) -> 2 | K32: =COUNTIF(K5:K28,0) -> 0 | ... N32: =COUNTIF(N5:N28,0) -> 0

Sheet SPECIAL LEVY
B2: SPECIAL LEVY
A3: ` | B3: NO. | C3: NAME | D3: TOTAL | E3: ELD. ISAAC DARKO | F3: ELD. SAMUEL NKANSAH | G3: ELD. SAMUEL NKANSAH | H3: ELD. JOHN OFOSUHENE ASARE | I3: ELD JONATHAN DANSO SIAW | J3: ELD PRINCE AHWIREN ASANTE
B4: 1 | C4: Alex Ackah | D4: =SUM(E4:N4) -> 700 | E4: 0 | F4: 0 | G4: 200 | H4: 200 | I4: 200 | J4: 100
B5: 2 | C5: Danso Kingsley | D5: =SUM(E5:N5) -> 100 | E5: 0 | F5: 0 | G5: 0 | H5: 0 | I5: 0 | J5: 100
B6: 3 | C6: Fanuel Hagan | D6: =SUM(E6:N6) -> 1000 | E6: 200 | F6: 100 | G6: 200 | H6: 200 | I6: 200 | J6: 100
B7: 4 | C7: Frederick Wortey Tawiah | D7: =SUM(E7:N7) -> 1000 | E7: 200 | F7: 100 | G7: 200 | H7: 200 | I7: 200 | J7: 100
B8: 5 | C8: George Yeboah | D8: =SUM(E8:N8) -> 100 | E8: 0 | F8: 0 | G8: 0 | H8: 0 | I8: 0 | J8: 100
B9: 6 | C9: Isaac Darko | D9: =SUM(E9:N9) -> 800 | E9: 0 | F9: 100 | G9: 200 | H9: 200 | I9: 200 | J9: 100
B10: 7 | C10: Isaac Donkor | D10: =SUM(E10:N10) -> 100 | E10: 0 | F10: 0 | G10: 0 | H10: 0 | I10: 0 | J10: 100
B11: 8 | C11: John Aidoo | D11: =SUM(E11:N11) -> 0 | E11: 0 | F11: 0 | G11: 0 | H11: 0 | I11: 0 | J11: 0
B12: 9 | C12: John Darbo | D12: =SUM(E12:N12) -> 100 | E12: 0 | F12: 0 | G12: 0 | H12: 0 | I12: 0 | J12: 100
B13: 10 | C13: John Ofosuhene Asare | D13: =SUM(E13:N13) -> 800 | E13: 200 | F13: 100 | G13: 200 | H13: 0 | I13: 200 | J13: 100
B14: 11 | C14: Johnson Wood | D14: =SUM(E14:N14) -> 1000 | E14: 200 | F14: 100 | G14: 200 | H14: 200 | I14: 200 | J14: 100
B15: 12 | C15: Jonas Wereko | D15: =SUM(E15:N15) -> 1000 | E15: 200 | F15: 100 | G15: 200 | H15: 200 | I15: 200 | J15: 100
... B27: 24 | C27: William Kojo Anane | D27: =SUM(E27:N27) -> 1000 | E27: 200 | F27: 100 | G27: 200 | H27: 200 | I27: 200 | J27: 100
B29: TOTAL | D29: =SUBTOTAL(9,D4:D27) -> 18100 | E29: =SUBTOTAL(9,E4:E27) -> 3400 | F29: =SUBTOTAL(9,F4:F27) -> 1700 | G29: =SUBTOTAL(9,G4:G27) -> 3600 | H29: =SUBTOTAL(9,H4:H27) -> 3600 | I29: =SUBTOTAL(9,I4:I27) -> 3600 | J29: =SUBTOTAL(9,J4:J27) -> 2200 | K29: =SUBTOTAL(9,K4:K27) -> 0 | ... N29: =SUBTOTAL(9,N4:N27) -> 0
B30: TOTAL MEMBERS PAID | D30: =COUNTIF(D4:D27,">0") -> 23 | E30: =COUNTIF(E4:E27,">0") -> 17 | F30: =COUNTIF(F4:F27,">0") -> 17 | G30: =COUNTIF(G4:G27,">0") -> 18 | H30: =COUNTIF(H4:H27,">0") -> 18 | I30: =COUNTIF(I4:I27,">0") -> 18 | J30: =COUNTIF(J4:J27,">0") -> 22 | K30: =COUNTIF(K4:K27,">0") -> 0 | ... N30: =COUNTIF(N4:N27,">0") -> 0
B31: TOTAL MEMBERS NOT PAID | D31: =COUNTIF(D4:D27,0) -> 1 | E31: =COUNTIF(E4:E27,0) -> 7 | F31: =COUNTIF(F4:F27,0) -> 7 | G31: =COUNTIF(G4:G27,0) -> 6 | H31: =COUNTIF(H4:H27,0) -> 6 | I31: =COUNTIF(I4:I27,0) -> 6 | J31: =COUNTIF(J4:J27,0) -> 2 | K31: =COUNTIF(K4:K27,0) -> 0 | ... N31: =COUNTIF(N4:N27,0) -> 0

Sheet LEVY DISBURSMENT
B2: DISBURSEMENT | N2: TRAIL BALANCE
A3: 1 | B3: ELD. ISAAC DARKO (FUNERAL)
B4: DATE | C4: FIRST CONTRIBUTION | D4: INCOME | E4: EXPENSES | F4: BALANCE
B5: 45157 | C5: Total Contribution | D5: ='SPECIAL LEVY'!E29 -> 3400 | F5: =D5 -> 3400
B6: 45158 | C6: Loan from Dues | D6: 400 | F6: =F5+D6-E6 -> 3800
B7: 45158 | C7: Mother's Funeral Donation | E7: 3140 | F7: =F6+D7-E7 -> 660
B8: 45158 | C8: Transportation to Nsawam (2 Members) | E8: 600 | F8: =F7+D8-E8 -> 60
B9: 45158 | C9: Taxes on MoMo | E9: =F6*1.5% -> 57 | F9: =F8+D9-E9 -> 3
B10: 45158 | C10: Balance C/F | F10: =F9+D10-E10 -> 3
B11: TOTAL & BALANCE | D11: =SUM(D5:D10) -> 3800 | E11: =SUM(E5:E10) -> 3797 | F11: =D11-E11 -> 3
A14: 2 | B14: ELD. SAMUEL YAW NKANSAH (CHILD NAMING)
B15: DATE | C15: SECOND CONTRIBUTION | D15: INCOME | E15: EXPENSES | F15: BALANCE
B16: =B10 -> 45158 | C16: Balance C/D | D16: =F10 -> 3 | F16: =D16 -> 3
B17: 45268 | C17: Total Contribution | D17: ='SPECIAL LEVY'!F29 -> 1700 | F17: =F16+D17-E17 -> 1703
B18: 45269 | C18: Child Naming Ceremony | E18: 1015 | F18: =F17+D18-E18 -> 688
B19: 45269 | C19: Transportation to Darkoman (2 Members) | E19: 400 | F19: =F18+D19-E19 -> 288
B20: 45269 | C20: Taxes on MoMo | E20: =1400*1.5% -> 21 | F20: =F19+D20-E20 -> 267
B21: 45269 | C21: Balance C/F | F21: =F20+D21-E21 -> 267
B22: TOTAL & BALANCE | D22: =SUM(D16:D21) -> 1703 | E22: =SUM(E16:E21) -> 1436 | F22: =D22-E22 -> 267
A25: 3 | B25: ELD. SAMUEL YAW NKANSAH (FUNERAL)
B26: DATE | C26: THIRD CONTRIBUTION | D26: INCOME | E26: EXPENSES | F26: BALANCE
B27: =B21 -> 45269 | C27: Balance C/D | D27: =F21 -> 267 | F27: =D27 -> 267
B28: 45594 | C28: Total Contribution | D28: ='SPECIAL LEVY'!G29 -> 3600 | F28: =F27+D28-E28 -> 3867
B29: 45595 | C29: Father's Funeral Donation | E29: 3040 | F29: =F28+D29-E29 -> 827
B30: 45595 | C30: Transportation to Akim Oda (2 Members) | E30: 600 | F30: =F29+D30-E30 -> 227
B31: 45595 | C31: Taxes on MoMo | E31: =3600*1.5% -> 54 | F31: =F30+D31-E31 -> 173
B32: 45595 | C32: Balance C/F | F32: =F31+D32-E32 -> 173
B33: TOTAL & BALANCE | D33: =SUM(D27:D32) -> 3867 | E33: =SUM(E27:E32) -> 3694 | F33: =D33-E33 -> 173
A36: 4 | B36: ELD. JOHN OFOSUHENE ASARE (FUNERAL)
B37: DATE | C37: FOURTH CONTRIBUTION | D37: INCOME | E37: EXPENSES | F37: BALANCE
B38: =B32 -> 45595 | C38: Balance C/D | D38: =F32 -> 173 | F38: =D38 -> 173
B39: 45615 | C39: Total Contribution | D39: ='SPECIAL LEVY'!H29 -> 3600 | F39: =F38+D39-E39 -> 3773
B40: 45616 | C40: Father's Funeral Donation | E40: 3040 | F40: =F39+D40-E40 -> 733
B41: 45616 | C41: Transportation to Akim Asuom (2 Members) | E41: 600 | F41: =F40+D41-E41 -> 133
B42: 45616 | C42: Taxes on MoMo | E42: =3600*1.5% -> 54 | F42: =F41+D42-E42 -> 79
B43: 45616 | C43: Balance C/F | F43: =F42+D43-E43 -> 79
B44: TOTAL & BALANCE | D44: =SUM(D38:D43) -> 3773 | E44: =SUM(E38:E43) -> 3694 | F44: =D44-E44 -> 79
A47: 5 | B47: ELD JONATHAN DANSO SIAW (FUNERAL)
B48: DATE | C48: FIFTH CONTRIBUTION | D48: INCOME | E48: EXPENSES | F48: BALANCE
B49: =B43 -> 45616 | C49: Balance C/D | D49: =F44 -> 79 | F49: =D49 -> 79
...

Sheet LEVY ACCOUNT
B2: DISBURSEMENT OF ACCOUNT
B3: DATE | C3: PARTICULARS | D3: INCOME | E3: EXPENSES | F3: BALANCE | G3: FUNERAL | H3: CHILD NAMING | I3: T & T | J3: MOMO TAXES
B4: ='LEVY DISBURSMENT'!B6 -> 45158 | C4: ELD. ISAAC DARKO (FUNERAL) | D4: ='LEVY DISBURSMENT'!F6 -> 3800 | E4: =SUM(G4:K4) -> 3797 | F4: =D4-E4 -> 3 | G4: ='LEVY DISBURSMENT'!E7 -> 3140 | I4: ='LEVY DISBURSMENT'!E8 -> 600 | J4: ='LEVY DISBURSMENT'!E9 -> 57
B5: ='LEVY DISBURSMENT'!B18 -> 45269 | C5: ELD. SAMUEL YAW NKANSAH (CHILD NAMING) | D5: ='LEVY DISBURSMENT'!D17 -> 1700 | E5: =SUM(G5:K5) -> 1436 | F5: =F4+D5-E5 -> 267 | H5: ='LEVY DISBURSMENT'!E18 -> 1015 | I5: ='LEVY DISBURSMENT'!E19 -> 400 | J5: ='LEVY DISBURSMENT'!E20 -> 21
B6: ='LEVY DISBURSMENT'!B29 -> 45595 | C6: ELD. SAMUEL YAW NKANSAH (FUNERAL) | D6: ='LEVY DISBURSMENT'!D28 -> 3600 | E6: =SUM(G6:K6) -> 3694 | F6: =F5+D6-E6 -> 173 | G6: ='LEVY DISBURSMENT'!E29 -> 3040 | I6: ='LEVY DISBURSMENT'!E30 -> 600 | J6: ='LEVY DISBURSMENT'!E31 -> 54
B7: ='LEVY DISBURSMENT'!B40 -> 45616 | C7: ELD. JOHN OFOSUHENE ASARE (FUNERAL) | D7: ='LEVY DISBURSMENT'!D39 -> 3600 | E7: =SUM(G7:K7) -> 3694 | F7: =F6+D7-E7 -> 79 | G7: ='LEVY DISBURSMENT'!E40 -> 3040 | I7: ='LEVY DISBURSMENT'!E41 -> 600 | J7: ='LEVY DISBURSMENT'!E42 -> 54
B8: ='LEVY DISBURSMENT'!B51 -> 45648 | C8: ELD JONATHAN DANSO SIAW (FUNERAL) | D8: ='LEVY DISBURSMENT'!D50 -> 3600 | E8: =SUM(G8:K8) -> 3091 | F8: =F7+D8-E8 -> 588 | G8: ='LEVY DISBURSMENT'!E51 -> 3040 | J8: ='LEVY DISBURSMENT'!E52 -> 51
B9: ='LEVY DISBURSMENT'!B61 -> 45807 | C9: ELD PRINCE AHWIREN ASANTE (CHILD NAMING) | D9: ='LEVY DISBURSMENT'!D60 -> 2200 | E9: =SUM(G9:K9) -> 1537.5 | F9: =F8+D9-E9 -> 1250.5 | H9: ='LEVY DISBURSMENT'!E61 -> 1015 | I9: ='LEVY DISBURSMENT'!E62 -> 500 | J9: ='LEVY DISBURSMENT'!E63 -> 22.5
E10: =SUM(G10:K10) -> 0 | F10: =F9+D10-E10 -> 1250.5
E11: =SUM(G11:K11) -> 0 | F11: =F10+D11-E11 -> 1250.5
E12: =SUM(G12:K12) -> 0 | F12: =F11+D12-E12 -> 1250.5
E13: =SUM(G13:K13) -> 0 | F13: =F12+D13-E13 -> 1250.5
E14: =SUM(G14:K14) -> 0 | F14: =F13+D14-E14 -> 1250.5
E15: =SUM(G15:K15) -> 0 | F15: =F14+D15-E15 -> 1250.5
E16: =SUM(G16:K16) -> 0 | F16: =F15+D16-E16 -> 1250.5
E17: =SUM(G17:K17) -> 0 | F17: =F16+D17-E17 -> 1250.5
E18: =SUM(G18:K18) -> 0 | F18: =F17+D18-E18 -> 1250.5
E19: =SUM(G19:K19) -> 0 | F19: =F18+D19-E19 -> 1250.5
E20: =SUM(G20:K20) -> 0 | F20: =F19+D20-E20 -> 1250.5
E21: =SUM(G21:K21) -> 0 | F21: =F20+D21-E21 -> 1250.5
... E23: =SUM(G23:K23) -> 0 | F23: =F22+D23-E23 -> 1250.5
B24: TOTAL | D24: =SUM(D4:D23) -> 18500 | E24: =SUM(E4:E23) -> 17249.5 | F24: =D24-E24 -> 1250.5 | G24: =SUM(G4:G23) -> 12260 | H24: =SUM(H4:H23) -> 2030 | I24: =SUM(I4:I23) -> 2700 | J24: =SUM(J4:J23) -> 259.5 | K24: =SUM(K4:K23) -> 0

Sheet LEVY TRAIL BALANCE
B2: TRAIL BALANCE
B3: PARTICULARS | C3: INCOME | D3: EXPENCES
C4: ¢ | D4: ¢
B5: Special Levy No 1 | C5: ='LEVY ACCOUNT'!D4 -> 3800
B6: Special Levy No 2 | C6: ='LEVY ACCOUNT'!D5 -> 1700
B7: Special Levy No 3 | C7: ='LEVY ACCOUNT'!D6 -> 3600
B8: Special Levy No 4 | C8: ='LEVY ACCOUNT'!D7 -> 3600
B9: Special Levy No 5 | C9: ='LEVY ACCOUNT'!D8 -> 3600
B10: Special Levy No 6 | C10: ='LEVY ACCOUNT'!D9 -> 2200
B11: Funeral Donations | D11: ='LEVY ACCOUNT'!G24 -> 12260
B12: Child Naming Donations | D12: ='LEVY ACCOUNT'!H24 -> 2030
B13: Transportations | D13: ='LEVY ACCOUNT'!I24 -> 2700
B14: MoMo Charges | D14: ='LEVY ACCOUNT'!J24 -> 259.5
B15: Balance on MoMo Account | D15: ='LEVY ACCOUNT'!F24 -> 1250.5
B18: TOTAL | C18: =SUM(C5:C17) -> 18500 | D18: =SUM(D5:D16) -> 18500

Sheet MTN MOMO ACCOUNT
B2: MTN MOMO ACCOUNTS
B3: DATE | C3: PARTICULARS | D3: INCOME | E3: EXPENSES | F3: BALANCE | G3: REGISTRATION FEE | H3: DUES 2023 | I3: DUES 2024 | J3: DUES 2025 | K3: DUES 2026 | L3: DUES 2027 | M3: SPECIAL LEVY 1 | N3: SPECIAL LEVY 2 | O3: SPECIAL LEVY 3 | P3: SPECIAL LEVY 4 | Q3: SPECIAL LEVY 5 | R3: SPECIAL LEVY 6 | S3: MOMO INTREST | T3: BANK WITHDRAWAL | U3: LEVY BALANCE | V3: SPECIAL CONTRIBUTION | W3: DUES ACCOUNTS | X3: LEVY ACCOUNT
B4: 1044 | C4: MOMO: '0530486443 - MECHANT: 293658 | D4: ¢ | E4: ¢ | F4: ¢ | G4: ¢ | H4: ¢ | I4: ¢ | J4: ¢ | K4: ¢ | M4: ¢ | N4: ¢ | O4: ¢ | P4: ¢ | Q4: ¢ | R4: ¢ | S4: ¢ | W4: ¢ | X4: ¢ | Y4: ¢
B5: 1 | C5: Alex Ackah | D5: =SUM(G5:V5) -> 3900 | F5: =D5 -> 3900 | G5: =IFERROR(VLOOKUP($C5,'MEMBERS LIST'!$D$5:$AT$28,32,0),0) -> 200 | H5: =IFERROR(VLOOKUP($C5,'MONTHLY DUES 2023'!$C$5:$D$23,2,0),0) -> 0 | I5: =IFERROR(VLOOKUP($C5,'MONTHLY DUES 2024'!$C$5:$D$25,2,0),0) -> 900 | J5: =IFERROR(VLOOKUP($C5,'MONTHLY DUES 2025'!$C$5:$D$26,2,0),0) -> 1200 | K5: =IFERROR(VLOOKUP($C5,'MONTHLY DUES 2026'!$C$5:$D$23,2,0),0) -> 900 | M5: =IFERROR(VLOOKUP($C5,'SPECIAL LEVY'!$C$4:$N$27,3,0),0) -> 0 | N5: =IFERROR(VLOOKUP($C5,'SPECIAL LEVY'!$C$4:$N$27,4,0),0) -> 0 | O5: =IFERROR(VLOOKUP($C5,'SPECIAL LEVY'!$C$4:$N$27,5,0),0) -> 200 | P5: =IFERROR(VLOOKUP($C5,'SPECIAL LEVY'!$C$4:$N$27,6,0),0) -> 200 | Q5: =IFERROR(VLOOKUP($C5,'SPECIAL LEVY'!$C$4:$N$27,7,0),0) -> 200 | R5: =IFERROR(VLOOKUP($C5,'SPECIAL LEVY'!$C$4:$J$27,8,0),0) -> 100
